Workbook
Name ListeProduits: Produits!$B$5:$B$104
Name ListeFournisseurs: Listes!$B$4:$B$100
Name ListeClients: Listes!$C$4:$C$100
Name ListeSKU: Produits!$A$5:$A$104

Sheet Dashboard
A1: DASHBOARD — ACTIVITÉ COMMERCIALE | Z1: Catégorie | AA1: Stock
A2: Feuille 100 % automatique. | Z2: PC portable | AA2: =SUMIF(Produits!$K$5:$K$19,Z2,Produits!$H$5:$H$19)
Z3: PC fixe | AA3: =SUMIF(Produits!$K$5:$K$19,Z3,Produits!$H$5:$H$19)
A4: STOCK TOTAL (unités) | C4: CHIFFRE D'AFFAIRES | E4: BÉNÉFICE BRUT | H4: À COMMANDER | Z4: Écran | AA4: =SUMIF(Produits!$K$5:$K$19,Z4,Produits!$H$5:$H$19)
A5: =SUM(Produits!$H$5:$H$104) | C5: =SUM(Ventes!$F$5:$F$104) | E5: =SUM(Ventes!$G$5:$G$104) | H5: =COUNTIF(Produits!$I$5:$I$104,"A COMMANDER") | Z5: Composant | AA5: =SUMIF(Produits!$K$5:$K$19,Z5,Produits!$H$5:$H$19)
A6: dont ce mois : | C6: =SUMPRODUCT((TEXT(Ventes!$A$5:$A$104,"YYYY-MM")=TEXT(TODAY(),"YYYY-MM"))*Ventes!$F$5:$F$104) | E6: =SUMPRODUCT((TEXT(Ventes!$A$5:$A$104,"YYYY-MM")=TEXT(TODAY(),"YYYY-MM"))*Ventes!$G$5:$G$104) | Z6: Accessoire | AA6: =SUMIF(Produits!$K$5:$K$19,Z6,Produits!$H$5:$H$19)
A7: PRODUITS A COMMANDER | F7: 10 DERNIERES VENTES | L7: 10 DERNIERS ACHATS
A8: SKU | B8: Produit | C8: Stock | D8: Seuil | F8: Date | G8: SKU | H8: Client | I8: Qté | J8: CA | L8: Date | M8: SKU | N8: Qté
A9: =IFERROR(INDEX(Produits!$A$5:$A$19,MATCH(1,Produits!$L$5:$L$19,0)),"") | B9: =IF($A9="","",INDEX(Produits!$B:$B,MATCH($A9,Produits!$A:$A,0))) | C9: =IF($A9="","",INDEX(Produits!$H:$H,MATCH($A9,Produits!$A:$A,0))) | D9: =IF($A9="","",INDEX(Produits!$J:$J,MATCH($A9,Produits!$A:$A,0))) | F9: =IFERROR(INDEX(Ventes!$A$5:$A$104,MATCH(COUNT(Ventes!$H$5:$H$104)-ROWS($F$9:F9)+1,Ventes!$H$5:$H$104,0)),"") | G9: =IF($F9="","",INDEX(Ventes!$C$5:$C$104,MATCH(COUNT(Ventes!$H$5:$H$104)-ROWS($F$9:F9)+1,Ventes!$H$5:$H$104,0))) | H9: =IF($F9="","",INDEX(Ventes!$E$5:$E$104,MATCH(COUNT(Ventes!$H$5:$H$104)-ROWS($F$9:F9)+1,Ventes!$H$5:$H$104,0))) | I9: =IF($F9="","",INDEX(Ventes!$D$5:$D$104,MATCH(COUNT(Ventes!$H$5:$H$104)-ROWS($F$9:F9)+1,Ventes!$H$5:$H$104,0))) | J9: =IF($F9="","",INDEX(Ventes!$F$5:$F$104,MATCH(COUNT(Ventes!$H$5:$H$104)-ROWS($F$9:F9)+1,Ventes!$H$5:$H$104,0))) | L9: =IFERROR(INDEX(Achats!$A$5:$A$104,MATCH(COUNT(Achats!$F$5:$F$104)-ROWS($L$9:L9)+1,Achats!$F$5:$F$104,0)),"") | M9: =IF($L9="","",INDEX(Achats!$C$5:$C$104,MATCH(COUNT(Achats!$F$5:$F$104)-ROWS($L$9:L9)+1,Achats!$F$5:$F$104,0))) | N9: =IF($L9="","",INDEX(Achats!$D$5:$D$104,MATCH(COUNT(Achats!$F$5:$F$104)-ROWS($L$9:L9)+1,Achats!$F$5:$F$104,0)))
A10: =IFERROR(INDEX(Produits!$A$5:$A$19,MATCH(2,Produits!$L$5:$L$19,0)),"") | B10: =IF($A10="","",INDEX(Produits!$B:$B,MATCH($A10,Produits!$A:$A,0))) | C10: =IF($A10="","",INDEX(Produits!$H:$H,MATCH($A10,Produits!$A:$A,0))) | D10: =IF($A10="","",INDEX(Produits!$J:$J,MATCH($A10,Produits!$A:$A,0))) | F10: =IFERROR(INDEX(Ventes!$A$5:$A$104,MATCH(COUNT(Ventes!$H$5:$H$104)-ROWS($F$9:F10)+1,Ventes!$H$5:$H$104,0)),"") | G10: =IF($F10="","",INDEX(Ventes!$C$5:$C$104,MATCH(COUNT(Ventes!$H$5:$H$104)-ROWS($F$9:F10)+1,Ventes!$H$5:$H$104,0))) | H10: =IF($F10="","",INDEX(Ventes!$E$5:$E$104,MATCH(COUNT(Ventes!$H$5:$H$104)-ROWS($F$9:F10)+1,Ventes!$H$5:$H$104,0))) | I10: =IF($F10="","",INDEX(Ventes!$D$5:$D$104,MATCH(COUNT(Ventes!$H$5:$H$104)-ROWS($F$9:F10)+1,Ventes!$H$5:$H$104,0))) | J10: =IF($F10="","",INDEX(Ventes!$F$5:$F$104,MATCH(COUNT(Ventes!$H$5:$H$104)-ROWS($F$9:F10)+1,Ventes!$H$5:$H$104,0))) | L10: =IFERROR(INDEX(Achats!$A$5:$A$104,MATCH(COUNT(Achats!$F$5:$F$104)-ROWS($L$9:L10)+1,Achats!$F$5:$F$104,0)),"") | M10: =IF($L10="","",INDEX(Achats!$C$5:$C$104,MATCH(COUNT(Achats!$F$5:$F$104)-ROWS($L$9:L10)+1,Achats!$F$5:$F$104,0))) | N10: =IF($L10="","",INDEX(Achats!$D$5:$D$104,MATCH(COUNT(Achats!$F$5:$F$104)-ROWS($L$9:L10)+1,Achats!$F$5:$F$104,0)))
A11: =IFERROR(INDEX(Produits!$A$5:$A$19,MATCH(3,Produits!$L$5:$L$19,0)),"") | B11: =IF($A11="","",INDEX(Produits!$B:$B,MATCH($A11,Produits!$A:$A,0))) | C11: =IF($A11="","",INDEX(Produits!$H:$H,MATCH($A11,Produits!$A:$A,0))) | D11: =IF($A11="","",INDEX(Produits!$J:$J,MATCH($A11,Produits!$A:$A,0))) | F11: =IFERROR(INDEX(Ventes!$A$5:$A$104,MATCH(COUNT(Ventes!$H$5:$H$104)-ROWS($F$9:F11)+1,Ventes!$H$5:$H$104,0)),"") | G11: =IF($F11="","",INDEX(Ventes!$C$5:$C$104,MATCH(COUNT(Ventes!$H$5:$H$104)-ROWS($F$9:F11)+1,Ventes!$H$5:$H$104,0))) | H11: =IF($F11="","",INDEX(Ventes!$E$5:$E$104,MATCH(COUNT(Ventes!$H$5:$H$104)-ROWS($F$9:F11)+1,Ventes!$H$5:$H$104,0))) | I11: =IF($F11="","",INDEX(Ventes!$D$5:$D$104,MATCH(COUNT(Ventes!$H$5:$H$104)-ROWS($F$9:F11)+1,Ventes!$H$5:$H$104,0))) | J11: =IF($F11="","",INDEX(Ventes!$F$5:$F$104,MATCH(COUNT(Ventes!$H$5:$H$104)-ROWS($F$9:F11)+1,Ventes!$H$5:$H$104,0))) | L11: =IFERROR(INDEX(Achats!$A$5:$A$104,MATCH(COUNT(Achats!$F$5:$F$104)-ROWS($L$9:L11)+1,Achats!$F$5:$F$104,0)),"") | M11: =IF($L11="","",INDEX(Achats!$C$5:$C$104,MATCH(COUNT(Achats!$F$5:$F$104)-ROWS($L$9:L11)+1,Achats!$F$5:$F$104,0))) | N11: =IF($L11="","",INDEX(Achats!$D$5:$D$104,MATCH(COUNT(Achats!$F$5:$F$104)-ROWS($L$9:L11)+1,Achats!$F$5:$F$104,0)))
A12: =IFERROR(INDEX(Produits!$A$5:$A$19,MATCH(4,Produits!$L$5:$L$19,0)),"") | B12: =IF($A12="","",INDEX(Produits!$B:$B,MATCH($A12,Produits!$A:$A,0))) | C12: =IF($A12="","",INDEX(Produits!$H:$H,MATCH($A12,Produits!$A:$A,0))) | D12: =IF($A12="","",INDEX(Produits!$J:$J,MATCH($A12,Produits!$A:$A,0))) | F12: =IFERROR(INDEX(Ventes!$A$5:$A$104,MATCH(COUNT(Ventes!$H$5:$H$104)-ROWS($F$9:F12)+1,Ventes!$H$5:$H$104,0)),"") | G12: =IF($F12="","",INDEX(Ventes!$C$5:$C$104,MATCH(COUNT(Ventes!$H$5:$H$104)-ROWS($F$9:F12)+1,Ventes!$H$5:$H$104,0))) | H12: =IF($F12="","",INDEX(Ventes!$E$5:$E$104,MATCH(COUNT(Ventes!$H$5:$H$104)-ROWS($F$9:F12)+1,Ventes!$H$5:$H$104,0))) | I12: =IF($F12="","",INDEX(Ventes!$D$5:$D$104,MATCH(COUNT(Ventes!$H$5:$H$104)-ROWS($F$9:F12)+1,Ventes!$H$5:$H$104,0))) | J12: =IF($F12="","",INDEX(Ventes!$F$5:$F$104,MATCH(COUNT(Ventes!$H$5:$H$104)-ROWS($F$9:F12)+1,Ventes!$H$5:$H$104,0))) | L12: =IFERROR(INDEX(Achats!$A$5:$A$104,MATCH(COUNT(Achats!$F$5:$F$104)-ROWS($L$9:L12)+1,Achats!$F$5:$F$104,0)),"") | M12: =IF($L12="","",INDEX(Achats!$C$5:$C$104,MATCH(COUNT(Achats!$F$5:$F$104)-ROWS($L$9:L12)+1,Achats!$F$5:$F$104,0))) | N12: =IF($L12="","",INDEX(Achats!$D$5:$D$104,MATCH(COUNT(Achats!$F$5:$F$104)-ROWS($L$9:L12)+1,Achats!$F$5:$F$104,0)))
A13: =IFERROR(INDEX(Produits!$A$5:$A$19,MATCH(5,Produits!$L$5:$L$19,0)),"") | B13: =IF($A13="","",INDEX(Produits!$B:$B,MATCH($A13,Produits!$A:$A,0))) | C13: =IF($A13="","",INDEX(Produits!$H:$H,MATCH($A13,Produits!$A:$A,0))) | D13: =IF($A13="","",INDEX(Produits!$J:$J,MATCH($A13,Produits!$A:$A,0))) | F13: =IFERROR(INDEX(Ventes!$A$5:$A$104,MATCH(COUNT(Ventes!$H$5:$H$104)-ROWS($F$9:F13)+1,Ventes!$H$5:$H$104,0)),"") | G13: =IF($F13="","",INDEX(Ventes!$C$5:$C$104,MATCH(COUNT(Ventes!$H$5:$H$104)-ROWS($F$9:F13)+1,Ventes!$H$5:$H$104,0))) | H13: =IF($F13="","",INDEX(Ventes!$E$5:$E$104,MATCH(COUNT(Ventes!$H$5:$H$104)-ROWS($F$9:F13)+1,Ventes!$H$5:$H$104,0))) | I13: =IF($F13="","",INDEX(Ventes!$D$5:$D$104,MATCH(COUNT(Ventes!$H$5:$H$104)-ROWS($F$9:F13)+1,Ventes!$H$5:$H$104,0))) | J13: =IF($F13="","",INDEX(Ventes!$F$5:$F$104,MATCH(COUNT(Ventes!$H$5:$H$104)-ROWS($F$9:F13)+1,Ventes!$H$5:$H$104,0))) | L13: =IFERROR(INDEX(Achats!$A$5:$A$104,MATCH(COUNT(Achats!$F$5:$F$104)-ROWS($L$9:L13)+1,Achats!$F$5:$F$104,0)),"") | M13: =IF($L13="","",INDEX(Achats!$C$5:$C$104,MATCH(COUNT(Achats!$F$5:$F$104)-ROWS($L$9:L13)+1,Achats!$F$5:$F$104,0))) | N13: =IF($L13="","",INDEX(Achats!$D$5:$D$104,MATCH(COUNT(Achats!$F$5:$F$104)-ROWS($L$9:L13)+1,Achats!$F$5:$F$104,0)))
A14: =IFERROR(INDEX(Produits!$A$5:$A$19,MATCH(6,Produits!$L$5:$L$19,0)),"") | B14: =IF($A14="","",INDEX(Produits!$B:$B,MATCH($A14,Produits!$A:$A,0))) | C14: =IF($A14="","",INDEX(Produits!$H:$H,MATCH($A14,Produits!$A:$A,0))) | D14: =IF($A14="","",INDEX(Produits!$J:$J,MATCH($A14,Produits!$A:$A,0))) | F14: =IFERROR(INDEX(Ventes!$A$5:$A$104,MATCH(COUNT(Ventes!$H$5:$H$104)-ROWS($F$9:F14)+1,Ventes!$H$5:$H$104,0)),"") | G14: =IF($F14="","",INDEX(Ventes!$C$5:$C$104,MATCH(COUNT(Ventes!$H$5:$H$104)-ROWS($F$9:F14)+1,Ventes!$H$5:$H$104,0))) | H14: =IF($F14="","",INDEX(Ventes!$E$5:$E$104,MATCH(COUNT(Ventes!$H$5:$H$104)-ROWS($F$9:F14)+1,Ventes!$H$5:$H$104,0))) | I14: =IF($F14="","",INDEX(Ventes!$D$5:$D$104,MATCH(COUNT(Ventes!$H$5:$H$104)-ROWS($F$9:F14)+1,Ventes!$H$5:$H$104,0))) | J14: =IF($F14="","",INDEX(Ventes!$F$5:$F$104,MATCH(COUNT(Ventes!$H$5:$H$104)-ROWS($F$9:F14)+1,Ventes!$H$5:$H$104,0))) | L14: =IFERROR(INDEX(Achats!$A$5:$A$104,MATCH(COUNT(Achats!$F$5:$F$104)-ROWS($L$9:L14)+1,Achats!$F$5:$F$104,0)),"") | M14: =IF($L14="","",INDEX(Achats!$C$5:$C$104,MATCH(COUNT(Achats!$F$5:$F$104)-ROWS($L$9:L14)+1,Achats!$F$5:$F$104,0))) | N14: =IF($L14="","",INDEX(Achats!$D$5:$D$104,MATCH(COUNT(Achats!$F$5:$F$104)-ROWS($L$9:L14)+1,Achats!$F$5:$F$104,0)))
A15: =IFERROR(INDEX(Produits!$A$5:$A$19,MATCH(7,Produits!$L$5:$L$19,0)),"") | B15: =IF($A15="","",INDEX(Produits!$B:$B,MATCH($A15,Produits!$A:$A,0))) | C15: =IF($A15="","",INDEX(Produits!$H:$H,MATCH($A15,Produits!$A:$A,0))) | D15: =IF($A15="","",INDEX(Produits!$J:$J,MATCH($A15,Produits!$A:$A,0))) | F15: =IFERROR(INDEX(Ventes!$A$5:$A$104,MATCH(COUNT(Ventes!$H$5:$H$104)-ROWS($F$9:F15)+1,Ventes!$H$5:$H$104,0)),"") | G15: =IF($F15="","",INDEX(Ventes!$C$5:$C$104,MATCH(COUNT(Ventes!$H$5:$H$104)-ROWS($F$9:F15)+1,Ventes!$H$5:$H$104,0))) | H15: =IF($F15="","",INDEX(Ventes!$E$5:$E$104,MATCH(COUNT(Ventes!$H$5:$H$104)-ROWS($F$9:F15)+1,Ventes!$H$5:$H$104,0))) | I15: =IF($F15="","",INDEX(Ventes!$D$5:$D$104,MATCH(COUNT(Ventes!$H$5:$H$104)-ROWS($F$9:F15)+1,Ventes!$H$5:$H$104,0))) | J15: =IF($F15="","",INDEX(Ventes!$F$5:$F$104,MATCH(COUNT(Ventes!$H$5:$H$104)-ROWS($F$9:F15)+1,Ventes!$H$5:$H$104,0))) | L15: =IFERROR(INDEX(Achats!$A$5:$A$104,MATCH(COUNT(Achats!$F$5:$F$104)-ROWS($L$9:L15)+1,Achats!$F$5:$F$104,0)),"") | M15: =IF($L15="","",INDEX(Achats!$C$5:$C$104,MATCH(COUNT(Achats!$F$5:$F$104)-ROWS($L$9:L15)+1,Achats!$F$5:$F$104,0))) | N15: =IF($L15="","",INDEX(Achats!$D$5:$D$104,MATCH(COUNT(Achats!$F$5:$F$104)-ROWS($L$9:L15)+1,Achats!$F$5:$F$104,0)))
A16: =IFERROR(INDEX(Produits!$A$5:$A$19,MATCH(8,Produits!$L$5:$L$19,0)),"") | B16: =IF($A16="","",INDEX(Produits!$B:$B,MATCH($A16,Produits!$A:$A,0))) | C16: =IF($A16="","",INDEX(Produits!$H:$H,MATCH($A16,Produits!$A:$A,0))) | D16: =IF($A16="","",INDEX(Produits!$J:$J,MATCH($A16,Produits!$A:$A,0))) | F16: =IFERROR(INDEX(Ventes!$A$5:$A$104,MATCH(COUNT(Ventes!$H$5:$H$104)-ROWS($F$9:F16)+1,Ventes!$H$5:$H$104,0)),"") | G16: =IF($F16="","",INDEX(Ventes!$C$5:$C$104,MATCH(COUNT(Ventes!$H$5:$H$104)-ROWS($F$9:F16)+1,Ventes!$H$5:$H$104,0))) | H16: =IF($F16="","",INDEX(Ventes!$E$5:$E$104,MATCH(COUNT(Ventes!$H$5:$H$104)-ROWS($F$9:F16)+1,Ventes!$H$5:$H$104,0))) | I16: =IF($F16="","",INDEX(Ventes!$D$5:$D$104,MATCH(COUNT(Ventes!$H$5:$H$104)-ROWS($F$9:F16)+1,Ventes!$H$5:$H$104,0))) | J16: =IF($F16="","",INDEX(Ventes!$F$5:$F$104,MATCH(COUNT(Ventes!$H$5:$H$104)-ROWS($F$9:F16)+1,Ventes!$H$5:$H$104,0))) | L16: =IFERROR(INDEX(Achats!$A$5:$A$104,MATCH(COUNT(Achats!$F$5:$F$104)-ROWS($L$9:L16)+1,Achats!$F$5:$F$104,0)),"") | M16: =IF($L16="","",INDEX(Achats!$C$5:$C$104,MATCH(COUNT(Achats!$F$5:$F$104)-ROWS($L$9:L16)+1,Achats!$F$5:$F$104,0))) | N16: =IF($L16="","",INDEX(Achats!$D$5:$D$104,MATCH(COUNT(Achats!$F$5:$F$104)-ROWS($L$9:L16)+1,Achats!$F$5:$F$104,0)))
A17: =IFERROR(INDEX(Produits!$A$5:$A$19,MATCH(9,Produits!$L$5:$L$19,0)),"") | B17: =IF($A17="","",INDEX(Produits!$B:$B,MATCH($A17,Produits!$A:$A,0))) | C17: =IF($A17="","",INDEX(Produits!$H:$H,MATCH($A17,Produits!$A:$A,0))) | D17: =IF($A17="","",INDEX(Produits!$J:$J,MATCH($A17,Produits!$A:$A,0))) | F17: =IFERROR(INDEX(Ventes!$A$5:$A$104,MATCH(COUNT(Ventes!$H$5:$H$104)-ROWS($F$9:F17)+1,Ventes!$H$5:$H$104,0)),"") | G17: =IF($F17="","",INDEX(Ventes!$C$5:$C$104,MATCH(COUNT(Ventes!$H$5:$H$104)-ROWS($F$9:F17)+1,Ventes!$H$5:$H$104,0))) | H17: =IF($F17="","",INDEX(Ventes!$E$5:$E$104,MATCH(COUNT(Ventes!$H$5:$H$104)-ROWS($F$9:F17)+1,Ventes!$H$5:$H$104,0))) | I17: =IF($F17="","",INDEX(Ventes!$D$5:$D$104,MATCH(COUNT(Ventes!$H$5:$H$104)-ROWS($F$9:F17)+1,Ventes!$H$5:$H$104,0))) | J17: =IF($F17="","",INDEX(Ventes!$F$5:$F$104,MATCH(COUNT(Ventes!$H$5:$H$104)-ROWS($F$9:F17)+1,Ventes!$H$5:$H$104,0))) | L17: =IFERROR(INDEX(Achats!$A$5:$A$104,MATCH(COUNT(Achats!$F$5:$F$104)-ROWS($L$9:L17)+1,Achats!$F$5:$F$104,0)),"") | M17: =IF($L17="","",INDEX(Achats!$C$5:$C$104,MATCH(COUNT(Achats!$F$5:$F$104)-ROWS($L$9:L17)+1,Achats!$F$5:$F$104,0))) | N17: =IF($L17="","",INDEX(Achats!$D$5:$D$104,MATCH(COUNT(Achats!$F$5:$F$104)-ROWS($L$9:L17)+1,Achats!$F$5:$F$104,0)))
A18: =IFERROR(INDEX(Produits!$A$5:$A$19,MATCH(10,Produits!$L$5:$L$19,0)),"") | B18: =IF($A18="","",INDEX(Produits!$B:$B,MATCH($A18,Produits!$A:$A,0))) | C18: =IF($A18="","",INDEX(Produits!$H:$H,MATCH($A18,Produits!$A:$A,0))) | D18: =IF($A18="","",INDEX(Produits!$J:$J,MATCH($A18,Produits!$A:$A,0))) | F18: =IFERROR(INDEX(Ventes!$A$5:$A$104,MATCH(COUNT(Ventes!$H$5:$H$104)-ROWS($F$9:F18)+1,Ventes!$H$5:$H$104,0)),"") | G18: =IF($F18="","",INDEX(Ventes!$C$5:$C$104,MATCH(COUNT(Ventes!$H$5:$H$104)-ROWS($F$9:F18)+1,Ventes!$H$5:$H$104,0))) | H18: =IF($F18="","",INDEX(Ventes!$E$5:$E$104,MATCH(COUNT(Ventes!$H$5:$H$104)-ROWS($F$9:F18)+1,Ventes!$H$5:$H$104,0))) | I18: =IF($F18="","",INDEX(Ventes!$D$5:$D$104,MATCH(COUNT(Ventes!$H$5:$H$104)-ROWS($F$9:F18)+1,Ventes!$H$5:$H$104,0))) | J18: =IF($F18="","",INDEX(Ventes!$F$5:$F$104,MATCH(COUNT(Ventes!$H$5:$H$104)-ROWS($F$9:F18)+1,Ventes!$H$5:$H$104,0))) | L18: =IFERROR(INDEX(Achats!$A$5:$A$104,MATCH(COUNT(Achats!$F$5:$F$104)-ROWS($L$9:L18)+1,Achats!$F$5:$F$104,0)),"") | M18: =IF($L18="","",INDEX(Achats!$C$5:$C$104,MATCH(COUNT(Achats!$F$5:$F$104)-ROWS($L$9:L18)+1,Achats!$F$5:$F$104,0))) | N18: =IF($L18="","",INDEX(Achats!$D$5:$D$104,MATCH(COUNT(Achats!$F$5:$F$104)-ROWS($L$9:L18)+1,Achats!$F$5:$F$104,0)))

Sheet Listes
A1: LISTES DE RÉFÉRENCE
A2: Feuille libre : ajoutez, modifiez ou supprimez les valeurs.
A3: SKU | B3: Fournisseurs | C3: Clients | D3: Produits
A4: PC-DELL-LAT5420 | B4: TechSource Cameroun | C4: Entreprise Mboa SARL | D4: Dell — Latitude 5420 i5/16Go/512Go
A5: PC-DELL-LAT7430 | B5: Digital Pro Yaoundé | C5: Cabinet Horizon | D5: Dell — Latitude 7430 i7/16Go/512Go
A6: PC-HP-EL840G8 | B6: Global IT Supply | C6: Client comptoir | D6: HP — EliteBook 840 G8 i5/16Go/512Go
A7: PC-HP-PR450G9 | C7: École Les Élites | D7: HP — ProBook 450 G9 i5/8Go/512Go
A8: PC-LEN-T14G2 | D8: Lenovo — ThinkPad T14 G2 i5/16Go/512Go
A9: PC-APPLE-MBA13 | D9: Apple — MacBook Air M1 8Go/256Go
A10: TOUR-DELL-OP7090 | D10: Dell — OptiPlex 7090 i5/16Go/512Go
A11: TOUR-HP-PR400G7 | D11: HP — ProDesk 400 G7 i5/8Go/256Go
A12: ECR-DELL-P2422H | D12: Dell — P2422H 24 pouces Full HD
A13: ECR-HP-E24G4 | D13: HP — E24 G4 24 pouces Full HD
A14: ECR-SAMS-S24R | D14: Samsung — S24R350 24 pouces Full HD
A15: COMP-SSD-512 | D15: Kingston — SSD NV2 512 Go
A16: COMP-RAM-16 | D16: Crucial — RAM DDR4 16 Go
A17: COMP-BAT-5420 | D17: Dell — Batterie Latitude 5420
A18: ACC-DELL-65W | D18: Dell — Chargeur USB-C 65 W

Sheet Produits
A1: PRODUITS
A2: Saisie libre : SKU, Produit, Prix, Stock, Seuil, Catégorie.
A4: SKU | B4: Produit | C4: Prix achat | D4: Prix vente | E4: Stock initial | F4: Entrées | G4: Ventes | H4: Stock actuel | I4: Alerte | J4: Seuil | K4: Catégorie | L4: Rang alerte
A5: PC-DELL-LAT5420 | B5: Dell — Latitude 5420 i5/16Go/512Go | C5: 365000 | D5: 485000 | E5: 4 | F5: =SUMIF(Achats!$C$5:$C$104,$A5,Achats!$D$5:$D$104) | G5: =SUMIF(Ventes!$C$5:$C$104,$A5,Ventes!$D$5:$D$104) | H5: =E5+F5-G5 | I5: =IF(H5<=J5,"A COMMANDER","OK") | J5: 2 | K5: PC portable | L5: =IF(I5="A COMMANDER",COUNTIF($I$5:I5,"A COMMANDER"),"")
A6: PC-DELL-LAT7430 | B6: Dell — Latitude 7430 i7/16Go/512Go | C6: 520000 | D6: 675000 | E6: 2 | F6: =SUMIF(Achats!$C$5:$C$104,$A6,Achats!$D$5:$D$104) | G6: =SUMIF(Ventes!$C$5:$C$104,$A6,Ventes!$D$5:$D$104) | H6: =E6+F6-G6 | I6: =IF(H6<=J6,"A COMMANDER","OK") | J6: 2 | K6: PC portable | L6: =IF(I6="A COMMANDER",COUNTIF($I$5:I6,"A COMMANDER"),"")
A7: PC-HP-EL840G8 | B7: HP — EliteBook 840 G8 i5/16Go/512Go | C7: 400000 | D7: 535000 | E7: 3 | F7: =SUMIF(Achats!$C$5:$C$104,$A7,Achats!$D$5:$D$104) | G7: =SUMIF(Ventes!$C$5:$C$104,$A7,Ventes!$D$5:$D$104) | H7: =E7+F7-G7 | I7: =IF(H7<=J7,"A COMMANDER","OK") | J7: 2 | K7: PC portable | L7: =IF(I7="A COMMANDER",COUNTIF($I$5:I7,"A COMMANDER"),"")
A8: PC-HP-PR450G9 | B8: HP — ProBook 450 G9 i5/8Go/512Go | C8: 350000 | D8: 465000 | E8: 3 | F8: =SUMIF(Achats!$C$5:$C$104,$A8,Achats!$D$5:$D$104) | G8: =SUMIF(Ventes!$C$5:$C$104,$A8,Ventes!$D$5:$D$104) | H8: =E8+F8-G8 | I8: =IF(H8<=J8,"A COMMANDER","OK") | J8: 2 | K8: PC portable | L8: =IF(I8="A COMMANDER",COUNTIF($I$5:I8,"A COMMANDER"),"")
A9: PC-LEN-T14G2 | B9: Lenovo — ThinkPad T14 G2 i5/16Go/512Go | C9: 390000 | D9: 520000 | E9: 2 | F9: =SUMIF(Achats!$C$5:$C$104,$A9,Achats!$D$5:$D$104) | G9: =SUMIF(Ventes!$C$5:$C$104,$A9,Ventes!$D$5:$D$104) | H9: =E9+F9-G9 | I9: =IF(H9<=J9,"A COMMANDER","OK") | J9: 2 | K9: PC portable | L9: =IF(I9="A COMMANDER",COUNTIF($I$5:I9,"A COMMANDER"),"")
A10: PC-APPLE-MBA13 | B10: Apple — MacBook Air M1 8Go/256Go | C10: 510000 | D10: 650000 | E10: 1 | F10: =SUMIF(Achats!$C$5:$C$104,$A10,Achats!$D$5:$D$104) | G10: =SUMIF(Ventes!$C$5:$C$104,$A10,Ventes!$D$5:$D$104) | H10: =E10+F10-G10 | I10: =IF(H10<=J10,"A COMMANDER","OK") | J10: 2 | K10: PC portable | L10: =IF(I10="A COMMANDER",COUNTIF($I$5:I10,"A COMMANDER"),"")
A11: TOUR-DELL-OP7090 | B11: Dell — OptiPlex 7090 i5/16Go/512Go | C11: 340000 | D11: 455000 | E11: 3 | F11: =SUMIF(Achats!$C$5:$C$104,$A11,Achats!$D$5:$D$104) | G11: =SUMIF(Ventes!$C$5:$C$104,$A11,Ventes!$D$5:$D$104) | H11: =E11+F11-G11 | I11: =IF(H11<=J11,"A COMMANDER","OK") | J11: 2 | K11: PC fixe | L11: =IF(I11="A COMMANDER",COUNTIF($I$5:I11,"A COMMANDER"),"")
A12: TOUR-HP-PR400G7 | B12: HP — ProDesk 400 G7 i5/8Go/256Go | C12: 250000 | D12: 345000 | E12: 2 | F12: =SUMIF(Achats!$C$5:$C$104,$A12,Achats!$D$5:$D$104) | G12: =SUMIF(Ventes!$C$5:$C$104,$A12,Ventes!$D$5:$D$104) | H12: =E12+F12-G12 | I12: =IF(H12<=J12,"A COMMANDER","OK") | J12: 2 | K12: PC fixe | L12: =IF(I12="A COMMANDER",COUNTIF($I$5:I12,"A COMMANDER"),"")
A13: ECR-DELL-P2422H | B13: Dell — P2422H 24 pouces Full HD | C13: 105000 | D13: 145000 | E13: 4 | F13: =SUMIF(Achats!$C$5:$C$104,$A13,Achats!$D$5:$D$104) | G13: =SUMIF(Ventes!$C$5:$C$104,$A13,Ventes!$D$5:$D$104) | H13: =E13+F13-G13 | I13: =IF(H13<=J13,"A COMMANDER","OK") | J13: 2 | K13: Écran | L13: =IF(I13="A COMMANDER",COUNTIF($I$5:I13,"A COMMANDER"),"")
A14: ECR-HP-E24G4 | B14: HP — E24 G4 24 pouces Full HD | C14: 95000 | D14: 130000 | E14: 2 | F14: =SUMIF(Achats!$C$5:$C$104,$A14,Achats!$D$5:$D$104) | G14: =SUMIF(Ventes!$C$5:$C$104,$A14,Ventes!$D$5:$D$104) | H14: =E14+F14-G14 | I14: =IF(H14<=J14,"A COMMANDER","OK") | J14: 2 | K14: Écran | L14: =IF(I14="A COMMANDER",COUNTIF($I$5:I14,"A COMMANDER"),"")
A15: ECR-SAMS-S24R | B15: Samsung — S24R350 24 pouces Full HD | C15: 85000 | D15: 120000 | E15: 3 | F15: =SUMIF(Achats!$C$5:$C$104,$A15,Achats!$D$5:$D$104) | G15: =SUMIF(Ventes!$C$5:$C$104,$A15,Ventes!$D$5:$D$104) | H15: =E15+F15-G15 | I15: =IF(H15<=J15,"A COMMANDER","OK") | J15: 2 | K15: Écran | L15: =IF(I15="A COMMANDER",COUNTIF($I$5:I15,"A COMMANDER"),"")
A16: COMP-SSD-512 | B16: Kingston — SSD NV2 512 Go | C16: 28000 | D16: 42000 | E16: 8 | F16: =SUMIF(Achats!$C$5:$C$104,$A16,Achats!$D$5:$D$104) | G16: =SUMIF(Ventes!$C$5:$C$104,$A16,Ventes!$D$5:$D$104) | H16: =E16+F16-G16 | I16: =IF(H16<=J16,"A COMMANDER","OK") | J16: 3 | K16: Composant | L16: =IF(I16="A COMMANDER",COUNTIF($I$5:I16,"A COMMANDER"),"")
... A19: ACC-DELL-65W | B19: Dell — Chargeur USB-C 65 W | C19: 18000 | D19: 30000 | E19: 5 | F19: =SUMIF(Achats!$C$5:$C$104,$A19,Achats!$D$5:$D$104) | G19: =SUMIF(Ventes!$C$5:$C$104,$A19,Ventes!$D$5:$D$104) | H19: =E19+F19-G19 | I19: =IF(H19<=J19,"A COMMANDER","OK") | J19: 2 | K19: Accessoire | L19: =IF(I19="A COMMANDER",COUNTIF($I$5:I19,"A COMMANDER"),"")

Sheet Achats
A2: Saisie : Date, Produit, Quantité, Fournisseur.
A4: Date | B4: Produit | C4: SKU (auto) | D4: Quantité | E4: Fournisseur | F4: Rang
A5: 46236 | B5: Dell — Latitude 5420 i5/16Go/512Go | C5: =IFERROR(INDEX(Produits!$A:$A,MATCH($B5,Produits!$B:$B,0)),"") | D5: 5 | E5: TechSource Cameroun | F5: =IF($A5="","",COUNT($A$5:A5))
A6: 46239 | B6: Kingston — SSD NV2 512 Go | C6: =IFERROR(INDEX(Produits!$A:$A,MATCH($B6,Produits!$B:$B,0)),"") | D6: 20 | E6: Digital Pro Yaoundé | F6: =IF($A6="","",COUNT($A$5:A6))
A7: 46268 | B7: HP — EliteBook 840 G8 i5/16Go/512Go | C7: =IFERROR(INDEX(Produits!$A:$A,MATCH($B7,Produits!$B:$B,0)),"") | D7: 3 | E7: TechSource Cameroun | F7: =IF($A7="","",COUNT($A$5:A7))
A8: 46275 | B8: Dell — Chargeur USB-C 65 W | C8: =IFERROR(INDEX(Produits!$A:$A,MATCH($B8,Produits!$B:$B,0)),"") | D8: 5 | E8: Global IT Supply | F8: =IF($A8="","",COUNT($A$5:A8))
A9: 46282 | B9: HP — EliteBook 840 G8 i5/16Go/512Go | C9: =IFERROR(INDEX(Produits!$A:$A,MATCH($B9,Produits!$B:$B,0)),"") | D9: 1 | E9: Digital Pro Yaoundé | F9: =IF($A9="","",COUNT($A$5:A9))
C10: =IFERROR(INDEX(Produits!$A:$A,MATCH($B10,Produits!$B:$B,0)),"") | F10: =IF($A10="","",COUNT($A$5:A10))
C11: =IFERROR(INDEX(Produits!$A:$A,MATCH($B11,Produits!$B:$B,0)),"") | F11: =IF($A11="","",COUNT($A$5:A11))
C12: =IFERROR(INDEX(Produits!$A:$A,MATCH($B12,Produits!$B:$B,0)),"") | F12: =IF($A12="","",COUNT($A$5:A12))
C13: =IFERROR(INDEX(Produits!$A:$A,MATCH($B13,Produits!$B:$B,0)),"") | F13: =IF($A13="","",COUNT($A$5:A13))
C14: =IFERROR(INDEX(Produits!$A:$A,MATCH($B14,Produits!$B:$B,0)),"") | F14: =IF($A14="","",COUNT($A$5:A14))
C15: =IFERROR(INDEX(Produits!$A:$A,MATCH($B15,Produits!$B:$B,0)),"") | F15: =IF($A15="","",COUNT($A$5:A15))
C16: =IFERROR(INDEX(Produits!$A:$A,MATCH($B16,Produits!$B:$B,0)),"") | F16: =IF($A16="","",COUNT($A$5:A16))
C17: =IFERROR(INDEX(Produits!$A:$A,MATCH($B17,Produits!$B:$B,0)),"") | F17: =IF($A17="","",COUNT($A$5:A17))
C18: =IFERROR(INDEX(Produits!$A:$A,MATCH($B18,Produits!$B:$B,0)),"") | F18: =IF($A18="","",COUNT($A$5:A18))
C19: =IFERROR(INDEX(Produits!$A:$A,MATCH($B19,Produits!$B:$B,0)),"") | F19: =IF($A19="","",COUNT($A$5:A19))
C20: =IFERROR(INDEX(Produits!$A:$A,MATCH($B20,Produits!$B:$B,0)),"") | F20: =IF($A20="","",COUNT($A$5:A20))
C21: =IFERROR(INDEX(Produits!$A:$A,MATCH($B21,Produits!$B:$B,0)),"") | F21: =IF($A21="","",COUNT($A$5:A21))
... C104: =IFERROR(INDEX(Produits!$A:$A,MATCH($B104,Produits!$B:$B,0)),"") | F104: =IF($A104="","",COUNT($A$5:A104))

Sheet Ventes
A2: Saisie : Date, Produit, Quantité, Client.
A4: Date | B4: Produit | C4: SKU (auto) | D4: Quantité | E4: Client | F4: CA | G4: Bénéfice | H4: Rang | I4: Clé jour
A5: 46252 | B5: Dell — Latitude 5420 i5/16Go/512Go | C5: =IFERROR(INDEX(Produits!$A:$A,MATCH($B5,Produits!$B:$B,0)),"") | D5: 2 | E5: Entreprise Mboa SARL | F5: =IFERROR(VLOOKUP($C5,Produits!$A$5:$D$104,4,0)*D5,0) | G5: =IFERROR((VLOOKUP($C5,Produits!$A$5:$D$104,4,0)-VLOOKUP($C5,Produits!$A$5:$C$104,3,0))*D5,0) | H5: =IF($A5="","",COUNT($A$5:A5)) | I5: =IF($A5="","",TEXT($A5,"YYYY-MM-DD")&"-"&COUNTIF($A$5:$A5,$A5))
A6: 46270 | B6: Dell — P2422H 24 pouces Full HD | C6: =IFERROR(INDEX(Produits!$A:$A,MATCH($B6,Produits!$B:$B,0)),"") | D6: 3 | E6: Cabinet Horizon | F6: =IFERROR(VLOOKUP($C6,Produits!$A$5:$D$104,4,0)*D6,0) | G6: =IFERROR((VLOOKUP($C6,Produits!$A$5:$D$104,4,0)-VLOOKUP($C6,Produits!$A$5:$C$104,3,0))*D6,0) | H6: =IF($A6="","",COUNT($A$5:A6)) | I6: =IF($A6="","",TEXT($A6,"YYYY-MM-DD")&"-"&COUNTIF($A$5:$A6,$A6))
A7: 46274 | B7: HP — EliteBook 840 G8 i5/16Go/512Go | C7: =IFERROR(INDEX(Produits!$A:$A,MATCH($B7,Produits!$B:$B,0)),"") | D7: 2 | E7: Entreprise Mboa SARL | F7: =IFERROR(VLOOKUP($C7,Produits!$A$5:$D$104,4,0)*D7,0) | G7: =IFERROR((VLOOKUP($C7,Produits!$A$5:$D$104,4,0)-VLOOKUP($C7,Produits!$A$5:$C$104,3,0))*D7,0) | H7: =IF($A7="","",COUNT($A$5:A7)) | I7: =IF($A7="","",TEXT($A7,"YYYY-MM-DD")&"-"&COUNTIF($A$5:$A7,$A7))
A8: 46280 | B8: Apple — MacBook Air M1 8Go/256Go | C8: =IFERROR(INDEX(Produits!$A:$A,MATCH($B8,Produits!$B:$B,0)),"") | D8: 1 | E8: Client comptoir | F8: =IFERROR(VLOOKUP($C8,Produits!$A$5:$D$104,4,0)*D8,0) | G8: =IFERROR((VLOOKUP($C8,Produits!$A$5:$D$104,4,0)-VLOOKUP($C8,Produits!$A$5:$C$104,3,0))*D8,0) | H8: =IF($A8="","",COUNT($A$5:A8)) | I8: =IF($A8="","",TEXT($A8,"YYYY-MM-DD")&"-"&COUNTIF($A$5:$A8,$A8))
A9: 46285 | B9: Dell — Latitude 7430 i7/16Go/512Go | C9: =IFERROR(INDEX(Produits!$A:$A,MATCH($B9,Produits!$B:$B,0)),"") | D9: 1 | E9: École Les Élites | F9: =IFERROR(VLOOKUP($C9,Produits!$A$5:$D$104,4,0)*D9,0) | G9: =IFERROR((VLOOKUP($C9,Produits!$A$5:$D$104,4,0)-VLOOKUP($C9,Produits!$A$5:$C$104,3,0))*D9,0) | H9: =IF($A9="","",COUNT($A$5:A9)) | I9: =IF($A9="","",TEXT($A9,"YYYY-MM-DD")&"-"&COUNTIF($A$5:$A9,$A9))
A10: 46282 | B10: Dell — Latitude 5420 i5/16Go/512Go | C10: =IFERROR(INDEX(Produits!$A:$A,MATCH($B10,Produits!$B:$B,0)),"") | D10: 1 | E10: Entreprise Mboa SARL | F10: =IFERROR(VLOOKUP($C10,Produits!$A$5:$D$104,4,0)*D10,0) | G10: =IFERROR((VLOOKUP($C10,Produits!$A$5:$D$104,4,0)-VLOOKUP($C10,Produits!$A$5:$C$104,3,0))*D10,0) | H10: =IF($A10="","",COUNT($A$5:A10)) | I10: =IF($A10="","",TEXT($A10,"YYYY-MM-DD")&"-"&COUNTIF($A$5:$A10,$A10))
C11: =IFERROR(INDEX(Produits!$A:$A,MATCH($B11,Produits!$B:$B,0)),"") | F11: =IFERROR(VLOOKUP($C11,Produits!$A$5:$D$104,4,0)*D11,0) | G11: =IFERROR((VLOOKUP($C11,Produits!$A$5:$D$104,4,0)-VLOOKUP($C11,Produits!$A$5:$C$104,3,0))*D11,0) | H11: =IF($A11="","",COUNT($A$5:A11)) | I11: =IF($A11="","",TEXT($A11,"YYYY-MM-DD")&"-"&COUNTIF($A$5:$A11,$A11))
C12: =IFERROR(INDEX(Produits!$A:$A,MATCH($B12,Produits!$B:$B,0)),"") | F12: =IFERROR(VLOOKUP($C12,Produits!$A$5:$D$104,4,0)*D12,0) | G12: =IFERROR((VLOOKUP($C12,Produits!$A$5:$D$104,4,0)-VLOOKUP($C12,Produits!$A$5:$C$104,3,0))*D12,0) | H12: =IF($A12="","",COUNT($A$5:A12)) | I12: =IF($A12="","",TEXT($A12,"YYYY-MM-DD")&"-"&COUNTIF($A$5:$A12,$A12))
C13: =IFERROR(INDEX(Produits!$A:$A,MATCH($B13,Produits!$B:$B,0)),"") | F13: =IFERROR(VLOOKUP($C13,Produits!$A$5:$D$104,4,0)*D13,0) | G13: =IFERROR((VLOOKUP($C13,Produits!$A$5:$D$104,4,0)-VLOOKUP($C13,Produits!$A$5:$C$104,3,0))*D13,0) | H13: =IF($A13="","",COUNT($A$5:A13)) | I13: =IF($A13="","",TEXT($A13,"YYYY-MM-DD")&"-"&COUNTIF($A$5:$A13,$A13))
C14: =IFERROR(INDEX(Produits!$A:$A,MATCH($B14,Produits!$B:$B,0)),"") | F14: =IFERROR(VLOOKUP($C14,Produits!$A$5:$D$104,4,0)*D14,0) | G14: =IFERROR((VLOOKUP($C14,Produits!$A$5:$D$104,4,0)-VLOOKUP($C14,Produits!$A$5:$C$104,3,0))*D14,0) | H14: =IF($A14="","",COUNT($A$5:A14)) | I14: =IF($A14="","",TEXT($A14,"YYYY-MM-DD")&"-"&COUNTIF($A$5:$A14,$A14))
C15: =IFERROR(INDEX(Produits!$A:$A,MATCH($B15,Produits!$B:$B,0)),"") | F15: =IFERROR(VLOOKUP($C15,Produits!$A$5:$D$104,4,0)*D15,0) | G15: =IFERROR((VLOOKUP($C15,Produits!$A$5:$D$104,4,0)-VLOOKUP($C15,Produits!$A$5:$C$104,3,0))*D15,0) | H15: =IF($A15="","",COUNT($A$5:A15)) | I15: =IF($A15="","",TEXT($A15,"YYYY-MM-DD")&"-"&COUNTIF($A$5:$A15,$A15))
C16: =IFERROR(INDEX(Produits!$A:$A,MATCH($B16,Produits!$B:$B,0)),"") | F16: =IFERROR(VLOOKUP($C16,Produits!$A$5:$D$104,4,0)*D16,0) | G16: =IFERROR((VLOOKUP($C16,Produits!$A$5:$D$104,4,0)-VLOOKUP($C16,Produits!$A$5:$C$104,3,0))*D16,0) | H16: =IF($A16="","",COUNT($A$5:A16)) | I16: =IF($A16="","",TEXT($A16,"YYYY-MM-DD")&"-"&COUNTIF($A$5:$A16,$A16))
C17: =IFERROR(INDEX(Produits!$A:$A,MATCH($B17,Produits!$B:$B,0)),"") | F17: =IFERROR(VLOOKUP($C17,Produits!$A$5:$D$104,4,0)*D17,0) | G17: =IFERROR((VLOOKUP($C17,Produits!$A$5:$D$104,4,0)-VLOOKUP($C17,Produits!$A$5:$C$104,3,0))*D17,0) | H17: =IF($A17="","",COUNT($A$5:A17)) | I17: =IF($A17="","",TEXT($A17,"YYYY-MM-DD")&"-"&COUNTIF($A$5:$A17,$A17))
C18: =IFERROR(INDEX(Produits!$A:$A,MATCH($B18,Produits!$B:$B,0)),"") | F18: =IFERROR(VLOOKUP($C18,Produits!$A$5:$D$104,4,0)*D18,0) | G18: =IFERROR((VLOOKUP($C18,Produits!$A$5:$D$104,4,0)-VLOOKUP($C18,Produits!$A$5:$C$104,3,0))*D18,0) | H18: =IF($A18="","",COUNT($A$5:A18)) | I18: =IF($A18="","",TEXT($A18,"YYYY-MM-DD")&"-"&COUNTIF($A$5:$A18,$A18))
C19: =IFERROR(INDEX(Produits!$A:$A,MATCH($B19,Produits!$B:$B,0)),"") | F19: =IFERROR(VLOOKUP($C19,Produits!$A$5:$D$104,4,0)*D19,0) | G19: =IFERROR((VLOOKUP($C19,Produits!$A$5:$D$104,4,0)-VLOOKUP($C19,Produits!$A$5:$C$104,3,0))*D19,0) | H19: =IF($A19="","",COUNT($A$5:A19)) | I19: =IF($A19="","",TEXT($A19,"YYYY-MM-DD")&"-"&COUNTIF($A$5:$A19,$A19))
C20: =IFERROR(INDEX(Produits!$A:$A,MATCH($B20,Produits!$B:$B,0)),"") | F20: =IFERROR(VLOOKUP($C20,Produits!$A$5:$D$104,4,0)*D20,0) | G20: =IFERROR((VLOOKUP($C20,Produits!$A$5:$D$104,4,0)-VLOOKUP($C20,Produits!$A$5:$C$104,3,0))*D20,0) | H20: =IF($A20="","",COUNT($A$5:A20)) | I20: =IF($A20="","",TEXT($A20,"YYYY-MM-DD")&"-"&COUNTIF($A$5:$A20,$A20))
C21: =IFERROR(INDEX(Produits!$A:$A,MATCH($B21,Produits!$B:$B,0)),"") | F21: =IFERROR(VLOOKUP($C21,Produits!$A$5:$D$104,4,0)*D21,0) | G21: =IFERROR((VLOOKUP($C21,Produits!$A$5:$D$104,4,0)-VLOOKUP($C21,Produits!$A$5:$C$104,3,0))*D21,0) | H21: =IF($A21="","",COUNT($A$5:A21)) | I21: =IF($A21="","",TEXT($A21,"YYYY-MM-DD")&"-"&COUNTIF($A$5:$A21,$A21))
C22: =IFERROR(INDEX(Produits!$A:$A,MATCH($B22,Produits!$B:$B,0)),"") | F22: =IFERROR(VLOOKUP($C22,Produits!$A$5:$D$104,4,0)*D22,0) | G22: =IFERROR((VLOOKUP($C22,Produits!$A$5:$D$104,4,0)-VLOOKUP($C22,Produits!$A$5:$C$104,3,0))*D22,0) | H22: =IF($A22="","",COUNT($A$5:A22)) | I22: =IF($A22="","",TEXT($A22,"YYYY-MM-DD")&"-"&COUNTIF($A$5:$A22,$A22))
... C104: =IFERROR(INDEX(Produits!$A:$A,MATCH($B104,Produits!$B:$B,0)),"") | F104: =IFERROR(VLOOKUP($C104,Produits!$A$5:$D$104,4,0)*D104,0) | G104: =IFERROR((VLOOKUP($C104,Produits!$A$5:$D$104,4,0)-VLOOKUP($C104,Produits!$A$5:$C$104,3,0))*D104,0) | H104: =IF($A104="","",COUNT($A$5:A104)) | I104: =IF($A104="","",TEXT($A104,"YYYY-MM-DD")&"-"&COUNTIF($A$5:$A104,$A104))

Sheet Calendrier 2026
A1: CALENDRIER 2026 — Synthèse journalière
A2: Feuille automatique — consultable et modifiable.
A4: Date | B4: Jour | C4: Nb ventes | D4: CA du jour | E4: Bénéfice du jour | F4: Nb achats | G4: Qté achetée
A5: 46023 | B5: Jeudi | C5: =COUNTIF(Ventes!$A$5:$A$104,$A5) | D5: =SUMPRODUCT((Ventes!$A$5:$A$104=$A5)*Ventes!$F$5:$F$104) | E5: =SUMPRODUCT((Ventes!$A$5:$A$104=$A5)*Ventes!$G$5:$G$104) | F5: =COUNTIF(Achats!$A$5:$A$104,$A5) | G5: =SUMIF(Achats!$A$5:$A$104,$A5,Achats!$D$5:$D$104)
A6: 46024 | B6: Vendredi | C6: =COUNTIF(Ventes!$A$5:$A$104,$A6) | D6: =SUMPRODUCT((Ventes!$A$5:$A$104=$A6)*Ventes!$F$5:$F$104) | E6: =SUMPRODUCT((Ventes!$A$5:$A$104=$A6)*Ventes!$G$5:$G$104) | F6: =COUNTIF(Achats!$A$5:$A$104,$A6) | G6: =SUMIF(Achats!$A$5:$A$104,$A6,Achats!$D$5:$D$104)
A7: 46025 | B7: Samedi | C7: =COUNTIF(Ventes!$A$5:$A$104,$A7) | D7: =SUMPRODUCT((Ventes!$A$5:$A$104=$A7)*Ventes!$F$5:$F$104) | E7: =SUMPRODUCT((Ventes!$A$5:$A$104=$A7)*Ventes!$G$5:$G$104) | F7: =COUNTIF(Achats!$A$5:$A$104,$A7) | G7: =SUMIF(Achats!$A$5:$A$104,$A7,Achats!$D$5:$D$104)
A8: 46026 | B8: Dimanche | C8: =COUNTIF(Ventes!$A$5:$A$104,$A8) | D8: =SUMPRODUCT((Ventes!$A$5:$A$104=$A8)*Ventes!$F$5:$F$104) | E8: =SUMPRODUCT((Ventes!$A$5:$A$104=$A8)*Ventes!$G$5:$G$104) | F8: =COUNTIF(Achats!$A$5:$A$104,$A8) | G8: =SUMIF(Achats!$A$5:$A$104,$A8,Achats!$D$5:$D$104)
A9: 46027 | B9: Lundi | C9: =COUNTIF(Ventes!$A$5:$A$104,$A9) | D9: =SUMPRODUCT((Ventes!$A$5:$A$104=$A9)*Ventes!$F$5:$F$104) | E9: =SUMPRODUCT((Ventes!$A$5:$A$104=$A9)*Ventes!$G$5:$G$104) | F9: =COUNTIF(Achats!$A$5:$A$104,$A9) | G9: =SUMIF(Achats!$A$5:$A$104,$A9,Achats!$D$5:$D$104)
A10: 46028 | B10: Mardi | C10: =COUNTIF(Ventes!$A$5:$A$104,$A10) | D10: =SUMPRODUCT((Ventes!$A$5:$A$104=$A10)*Ventes!$F$5:$F$104) | E10: =SUMPRODUCT((Ventes!$A$5:$A$104=$A10)*Ventes!$G$5:$G$104) | F10: =COUNTIF(Achats!$A$5:$A$104,$A10) | G10: =SUMIF(Achats!$A$5:$A$104,$A10,Achats!$D$5:$D$104)
A11: 46029 | B11: Mercredi | C11: =COUNTIF(Ventes!$A$5:$A$104,$A11) | D11: =SUMPRODUCT((Ventes!$A$5:$A$104=$A11)*Ventes!$F$5:$F$104) | E11: =SUMPRODUCT((Ventes!$A$5:$A$104=$A11)*Ventes!$G$5:$G$104) | F11: =COUNTIF(Achats!$A$5:$A$104,$A11) | G11: =SUMIF(Achats!$A$5:$A$104,$A11,Achats!$D$5:$D$104)
A12: 46030 | B12: Jeudi | C12: =COUNTIF(Ventes!$A$5:$A$104,$A12) | D12: =SUMPRODUCT((Ventes!$A$5:$A$104=$A12)*Ventes!$F$5:$F$104) | E12: =SUMPRODUCT((Ventes!$A$5:$A$104=$A12)*Ventes!$G$5:$G$104) | F12: =COUNTIF(Achats!$A$5:$A$104,$A12) | G12: =SUMIF(Achats!$A$5:$A$104,$A12,Achats!$D$5:$D$104)
A13: 46031 | B13: Vendredi | C13: =COUNTIF(Ventes!$A$5:$A$104,$A13) | D13: =SUMPRODUCT((Ventes!$A$5:$A$104=$A13)*Ventes!$F$5:$F$104) | E13: =SUMPRODUCT((Ventes!$A$5:$A$104=$A13)*Ventes!$G$5:$G$104) | F13: =COUNTIF(Achats!$A$5:$A$104,$A13) | G13: =SUMIF(Achats!$A$5:$A$104,$A13,Achats!$D$5:$D$104)
A14: 46032 | B14: Samedi | C14: =COUNTIF(Ventes!$A$5:$A$104,$A14) | D14: =SUMPRODUCT((Ventes!$A$5:$A$104=$A14)*Ventes!$F$5:$F$104) | E14: =SUMPRODUCT((Ventes!$A$5:$A$104=$A14)*Ventes!$G$5:$G$104) | F14: =COUNTIF(Achats!$A$5:$A$104,$A14) | G14: =SUMIF(Achats!$A$5:$A$104,$A14,Achats!$D$5:$D$104)
A15: 46033 | B15: Dimanche | C15: =COUNTIF(Ventes!$A$5:$A$104,$A15) | D15: =SUMPRODUCT((Ventes!$A$5:$A$104=$A15)*Ventes!$F$5:$F$104) | E15: =SUMPRODUCT((Ventes!$A$5:$A$104=$A15)*Ventes!$G$5:$G$104) | F15: =COUNTIF(Achats!$A$5:$A$104,$A15) | G15: =SUMIF(Achats!$A$5:$A$104,$A15,Achats!$D$5:$D$104)
A16: 46034 | B16: Lundi | C16: =COUNTIF(Ventes!$A$5:$A$104,$A16) | D16: =SUMPRODUCT((Ventes!$A$5:$A$104=$A16)*Ventes!$F$5:$F$104) | E16: =SUMPRODUCT((Ventes!$A$5:$A$104=$A16)*Ventes!$G$5:$G$104) | F16: =COUNTIF(Achats!$A$5:$A$104,$A16) | G16: =SUMIF(Achats!$A$5:$A$104,$A16,Achats!$D$5:$D$104)
... A369: 46387 | B369: Jeudi | C369: =COUNTIF(Ventes!$A$5:$A$104,$A369) | D369: =SUMPRODUCT((Ventes!$A$5:$A$104=$A369)*Ventes!$F$5:$F$104) | E369: =SUMPRODUCT((Ventes!$A$5:$A$104=$A369)*Ventes!$G$5:$G$104) | F369: =COUNTIF(Achats!$A$5:$A$104,$A369) | G369: =SUMIF(Achats!$A$5:$A$104,$A369,Achats!$D$5:$D$104)

Sheet Vue du jour
A1: VUE DU JOUR
A2: Choisissez une date en B3.
A3: Date : | B3: 46283
A5: Nb ventes | B5: =COUNTIF(Ventes!$A$5:$A$104,$B$3)
A6: CA du jour | B6: =SUMPRODUCT((Ventes!$A$5:$A$104=$B$3)*Ventes!$F$5:$F$104)
A7: Bénéfice | B7: =SUMPRODUCT((Ventes!$A$5:$A$104=$B$3)*Ventes!$G$5:$G$104)
A8: Nb achats | B8: =COUNTIF(Achats!$A$5:$A$104,$B$3)
A10: VENTES DU JOUR
A11: SKU | B11: Produit | C11: Qté | D11: Client | E11: CA | F11: Bénéfice
A12: =IFERROR(INDEX(Ventes!$C$5:$C$104,MATCH(TEXT($B$3,"YYYY-MM-DD")&"-"&1,Ventes!$I$5:$I$104,0)),"") | B12: =IF($A12="","",INDEX(Produits!$B:$B,MATCH($A12,Produits!$A:$A,0))) | C12: =IF($A12="","",INDEX(Ventes!$D$5:$D$104,MATCH(TEXT($B$3,"YYYY-MM-DD")&"-"&1,Ventes!$I$5:$I$104,0))) | D12: =IF($A12="","",INDEX(Ventes!$E$5:$E$104,MATCH(TEXT($B$3,"YYYY-MM-DD")&"-"&1,Ventes!$I$5:$I$104,0))) | E12: =IF($A12="","",INDEX(Ventes!$F$5:$F$104,MATCH(TEXT($B$3,"YYYY-MM-DD")&"-"&1,Ventes!$I$5:$I$104,0))) | F12: =IF($A12="","",INDEX(Ventes!$G$5:$G$104,MATCH(TEXT($B$3,"YYYY-MM-DD")&"-"&1,Ventes!$I$5:$I$104,0)))
A13: =IFERROR(INDEX(Ventes!$C$5:$C$104,MATCH(TEXT($B$3,"YYYY-MM-DD")&"-"&2,Ventes!$I$5:$I$104,0)),"") | B13: =IF($A13="","",INDEX(Produits!$B:$B,MATCH($A13,Produits!$A:$A,0))) | C13: =IF($A13="","",INDEX(Ventes!$D$5:$D$104,MATCH(TEXT($B$3,"YYYY-MM-DD")&"-"&2,Ventes!$I$5:$I$104,0))) | D13: =IF($A13="","",INDEX(Ventes!$E$5:$E$104,MATCH(TEXT($B$3,"YYYY-MM-DD")&"-"&2,Ventes!$I$5:$I$104,0))) | E13: =IF($A13="","",INDEX(Ventes!$F$5:$F$104,MATCH(TEXT($B$3,"YYYY-MM-DD")&"-"&2,Ventes!$I$5:$I$104,0))) | F13: =IF($A13="","",INDEX(Ventes!$G$5:$G$104,MATCH(TEXT($B$3,"YYYY-MM-DD")&"-"&2,Ventes!$I$5:$I$104,0)))
A14: =IFERROR(INDEX(Ventes!$C$5:$C$104,MATCH(TEXT($B$3,"YYYY-MM-DD")&"-"&3,Ventes!$I$5:$I$104,0)),"") | B14: =IF($A14="","",INDEX(Produits!$B:$B,MATCH($A14,Produits!$A:$A,0))) | C14: =IF($A14="","",INDEX(Ventes!$D$5:$D$104,MATCH(TEXT($B$3,"YYYY-MM-DD")&"-"&3,Ventes!$I$5:$I$104,0))) | D14: =IF($A14="","",INDEX(Ventes!$E$5:$E$104,MATCH(TEXT($B$3,"YYYY-MM-DD")&"-"&3,Ventes!$I$5:$I$104,0))) | E14: =IF($A14="","",INDEX(Ventes!$F$5:$F$104,MATCH(TEXT($B$3,"YYYY-MM-DD")&"-"&3,Ventes!$I$5:$I$104,0))) | F14: =IF($A14="","",INDEX(Ventes!$G$5:$G$104,MATCH(TEXT($B$3,"YYYY-MM-DD")&"-"&3,Ventes!$I$5:$I$104,0)))
A15: =IFERROR(INDEX(Ventes!$C$5:$C$104,MATCH(TEXT($B$3,"YYYY-MM-DD")&"-"&4,Ventes!$I$5:$I$104,0)),"") | B15: =IF($A15="","",INDEX(Produits!$B:$B,MATCH($A15,Produits!$A:$A,0))) | C15: =IF($A15="","",INDEX(Ventes!$D$5:$D$104,MATCH(TEXT($B$3,"YYYY-MM-DD")&"-"&4,Ventes!$I$5:$I$104,0))) | D15: =IF($A15="","",INDEX(Ventes!$E$5:$E$104,MATCH(TEXT($B$3,"YYYY-MM-DD")&"-"&4,Ventes!$I$5:$I$104,0))) | E15: =IF($A15="","",INDEX(Ventes!$F$5:$F$104,MATCH(TEXT($B$3,"YYYY-MM-DD")&"-"&4,Ventes!$I$5:$I$104,0))) | F15: =IF($A15="","",INDEX(Ventes!$G$5:$G$104,MATCH(TEXT($B$3,"YYYY-MM-DD")&"-"&4,Ventes!$I$5:$I$104,0)))
A16: =IFERROR(INDEX(Ventes!$C$5:$C$104,MATCH(TEXT($B$3,"YYYY-MM-DD")&"-"&5,Ventes!$I$5:$I$104,0)),"") | B16: =IF($A16="","",INDEX(Produits!$B:$B,MATCH($A16,Produits!$A:$A,0))) | C16: =IF($A16="","",INDEX(Ventes!$D$5:$D$104,MATCH(TEXT($B$3,"YYYY-MM-DD")&"-"&5,Ventes!$I$5:$I$104,0))) | D16: =IF($A16="","",INDEX(Ventes!$E$5:$E$104,MATCH(TEXT($B$3,"YYYY-MM-DD")&"-"&5,Ventes!$I$5:$I$104,0))) | E16: =IF($A16="","",INDEX(Ventes!$F$5:$F$104,MATCH(TEXT($B$3,"YYYY-MM-DD")&"-"&5,Ventes!$I$5:$I$104,0))) | F16: =IF($A16="","",INDEX(Ventes!$G$5:$G$104,MATCH(TEXT($B$3,"YYYY-MM-DD")&"-"&5,Ventes!$I$5:$I$104,0)))
A17: =IFERROR(INDEX(Ventes!$C$5:$C$104,MATCH(TEXT($B$3,"YYYY-MM-DD")&"-"&6,Ventes!$I$5:$I$104,0)),"") | B17: =IF($A17="","",INDEX(Produits!$B:$B,MATCH($A17,Produits!$A:$A,0))) | C17: =IF($A17="","",INDEX(Ventes!$D$5:$D$104,MATCH(TEXT($B$3,"YYYY-MM-DD")&"-"&6,Ventes!$I$5:$I$104,0))) | D17: =IF($A17="","",INDEX(Ventes!$E$5:$E$104,MATCH(TEXT($B$3,"YYYY-MM-DD")&"-"&6,Ventes!$I$5:$I$104,0))) | E17: =IF($A17="","",INDEX(Ventes!$F$5:$F$104,MATCH(TEXT($B$3,"YYYY-MM-DD")&"-"&6,Ventes!$I$5:$I$104,0))) | F17: =IF($A17="","",INDEX(Ventes!$G$5:$G$104,MATCH(TEXT($B$3,"YYYY-MM-DD")&"-"&6,Ventes!$I$5:$I$104,0)))
A18: =IFERROR(INDEX(Ventes!$C$5:$C$104,MATCH(TEXT($B$3,"YYYY-MM-DD")&"-"&7,Ventes!$I$5:$I$104,0)),"") | B18: =IF($A18="","",INDEX(Produits!$B:$B,MATCH($A18,Produits!$A:$A,0))) | C18: =IF($A18="","",INDEX(Ventes!$D$5:$D$104,MATCH(TEXT($B$3,"YYYY-MM-DD")&"-"&7,Ventes!$I$5:$I$104,0))) | D18: =IF($A18="","",INDEX(Ventes!$E$5:$E$104,MATCH(TEXT($B$3,"YYYY-MM-DD")&"-"&7,Ventes!$I$5:$I$104,0))) | E18: =IF($A18="","",INDEX(Ventes!$F$5:$F$104,MATCH(TEXT($B$3,"YYYY-MM-DD")&"-"&7,Ventes!$I$5:$I$104,0))) | F18: =IF($A18="","",INDEX(Ventes!$G$5:$G$104,MATCH(TEXT($B$3,"YYYY-MM-DD")&"-"&7,Ventes!$I$5:$I$104,0)))
A19: =IFERROR(INDEX(Ventes!$C$5:$C$104,MATCH(TEXT($B$3,"YYYY-MM-DD")&"-"&8,Ventes!$I$5:$I$104,0)),"") | B19: =IF($A19="","",INDEX(Produits!$B:$B,MATCH($A19,Produits!$A:$A,0))) | C19: =IF($A19="","",INDEX(Ventes!$D$5:$D$104,MATCH(TEXT($B$3,"YYYY-MM-DD")&"-"&8,Ventes!$I$5:$I$104,0))) | D19: =IF($A19="","",INDEX(Ventes!$E$5:$E$104,MATCH(TEXT($B$3,"YYYY-MM-DD")&"-"&8,Ventes!$I$5:$I$104,0))) | E19: =IF($A19="","",INDEX(Ventes!$F$5:$F$104,MATCH(TEXT($B$3,"YYYY-MM-DD")&"-"&8,Ventes!$I$5:$I$104,0))) | F19: =IF($A19="","",INDEX(Ventes!$G$5:$G$104,MATCH(TEXT($B$3,"YYYY-MM-DD")&"-"&8,Ventes!$I$5:$I$104,0)))
A20: =IFERROR(INDEX(Ventes!$C$5:$C$104,MATCH(TEXT($B$3,"YYYY-MM-DD")&"-"&9,Ventes!$I$5:$I$104,0)),"") | B20: =IF($A20="","",INDEX(Produits!$B:$B,MATCH($A20,Produits!$A:$A,0))) | C20: =IF($A20="","",INDEX(Ventes!$D$5:$D$104,MATCH(TEXT($B$3,"YYYY-MM-DD")&"-"&9,Ventes!$I$5:$I$104,0))) | D20: =IF($A20="","",INDEX(Ventes!$E$5:$E$104,MATCH(TEXT($B$3,"YYYY-MM-DD")&"-"&9,Ventes!$I$5:$I$104,0))) | E20: =IF($A20="","",INDEX(Ventes!$F$5:$F$104,MATCH(TEXT($B$3,"YYYY-MM-DD")&"-"&9,Ventes!$I$5:$I$104,0))) | F20: =IF($A20="","",INDEX(Ventes!$G$5:$G$104,MATCH(TEXT($B$3,"YYYY-MM-DD")&"-"&9,Ventes!$I$5:$I$104,0)))
A21: =IFERROR(INDEX(Ventes!$C$5:$C$104,MATCH(TEXT($B$3,"YYYY-MM-DD")&"-"&10,Ventes!$I$5:$I$104,0)),"") | B21: =IF($A21="","",INDEX(Produits!$B:$B,MATCH($A21,Produits!$A:$A,0))) | C21: =IF($A21="","",INDEX(Ventes!$D$5:$D$104,MATCH(TEXT($B$3,"YYYY-MM-DD")&"-"&10,Ventes!$I$5:$I$104,0))) | D21: =IF($A21="","",INDEX(Ventes!$E$5:$E$104,MATCH(TEXT($B$3,"YYYY-MM-DD")&"-"&10,Ventes!$I$5:$I$104,0))) | E21: =IF($A21="","",INDEX(Ventes!$F$5:$F$104,MATCH(TEXT($B$3,"YYYY-MM-DD")&"-"&10,Ventes!$I$5:$I$104,0))) | F21: =IF($A21="","",INDEX(Ventes!$G$5:$G$104,MATCH(TEXT($B$3,"YYYY-MM-DD")&"-"&10,Ventes!$I$5:$I$104,0)))
A22: =IFERROR(INDEX(Ventes!$C$5:$C$104,MATCH(TEXT($B$3,"YYYY-MM-DD")&"-"&11,Ventes!$I$5:$I$104,0)),"") | B22: =IF($A22="","",INDEX(Produits!$B:$B,MATCH($A22,Produits!$A:$A,0))) | C22: =IF($A22="","",INDEX(Ventes!$D$5:$D$104,MATCH(TEXT($B$3,"YYYY-MM-DD")&"-"&11,Ventes!$I$5:$I$104,0))) | D22: =IF($A22="","",INDEX(Ventes!$E$5:$E$104,MATCH(TEXT($B$3,"YYYY-MM-DD")&"-"&11,Ventes!$I$5:$I$104,0))) | E22: =IF($A22="","",INDEX(Ventes!$F$5:$F$104,MATCH(TEXT($B$3,"YYYY-MM-DD")&"-"&11,Ventes!$I$5:$I$104,0))) | F22: =IF($A22="","",INDEX(Ventes!$G$5:$G$104,MATCH(TEXT($B$3,"YYYY-MM-DD")&"-"&11,Ventes!$I$5:$I$104,0)))
A23: =IFERROR(INDEX(Ventes!$C$5:$C$104,MATCH(TEXT($B$3,"YYYY-MM-DD")&"-"&12,Ventes!$I$5:$I$104,0)),"") | B23: =IF($A23="","",INDEX(Produits!$B:$B,MATCH($A23,Produits!$A:$A,0))) | C23: =IF($A23="","",INDEX(Ventes!$D$5:$D$104,MATCH(TEXT($B$3,"YYYY-MM-DD")&"-"&12,Ventes!$I$5:$I$104,0))) | D23: =IF($A23="","",INDEX(Ventes!$E$5:$E$104,MATCH(TEXT($B$3,"YYYY-MM-DD")&"-"&12,Ventes!$I$5:$I$104,0))) | E23: =IF($A23="","",INDEX(Ventes!$F$5:$F$104,MATCH(TEXT($B$3,"YYYY-MM-DD")&"-"&12,Ventes!$I$5:$I$104,0))) | F23: =IF($A23="","",INDEX(Ventes!$G$5:$G$104,MATCH(TEXT($B$3,"YYYY-MM-DD")&"-"&12,Ventes!$I$5:$I$104,0)))
A24: =IFERROR(INDEX(Ventes!$C$5:$C$104,MATCH(TEXT($B$3,"YYYY-MM-DD")&"-"&13,Ventes!$I$5:$I$104,0)),"") | B24: =IF($A24="","",INDEX(Produits!$B:$B,MATCH($A24,Produits!$A:$A,0))) | C24: =IF($A24="","",INDEX(Ventes!$D$5:$D$104,MATCH(TEXT($B$3,"YYYY-MM-DD")&"-"&13,Ventes!$I$5:$I$104,0))) | D24: =IF($A24="","",INDEX(Ventes!$E$5:$E$104,MATCH(TEXT($B$3,"YYYY-MM-DD")&"-"&13,Ventes!$I$5:$I$104,0))) | E24: =IF($A24="","",INDEX(Ventes!$F$5:$F$104,MATCH(TEXT($B$3,"YYYY-MM-DD")&"-"&13,Ventes!$I$5:$I$104,0))) | F24: =IF($A24="","",INDEX(Ventes!$G$5:$G$104,MATCH(TEXT($B$3,"YYYY-MM-DD")&"-"&13,Ventes!$I$5:$I$104,0)))
A25: =IFERROR(INDEX(Ventes!$C$5:$C$104,MATCH(TEXT($B$3,"YYYY-MM-DD")&"-"&14,Ventes!$I$5:$I$104,0)),"") | B25: =IF($A25="","",INDEX(Produits!$B:$B,MATCH($A25,Produits!$A:$A,0))) | C25: =IF($A25="","",INDEX(Ventes!$D$5:$D$104,MATCH(TEXT($B$3,"YYYY-MM-DD")&"-"&14,Ventes!$I$5:$I$104,0))) | D25: =IF($A25="","",INDEX(Ventes!$E$5:$E$104,MATCH(TEXT($B$3,"YYYY-MM-DD")&"-"&14,Ventes!$I$5:$I$104,0))) | E25: =IF($A25="","",INDEX(Ventes!$F$5:$F$104,MATCH(TEXT($B$3,"YYYY-MM-DD")&"-"&14,Ventes!$I$5:$I$104,0))) | F25: =IF($A25="","",INDEX(Ventes!$G$5:$G$104,MATCH(TEXT($B$3,"YYYY-MM-DD")&"-"&14,Ventes!$I$5:$I$104,0)))
A26: =IFERROR(INDEX(Ventes!$C$5:$C$104,MATCH(TEXT($B$3,"YYYY-MM-DD")&"-"&15,Ventes!$I$5:$I$104,0)),"") | B26: =IF($A26="","",INDEX(Produits!$B:$B,MATCH($A26,Produits!$A:$A,0))) | C26: =IF($A26="","",INDEX(Ventes!$D$5:$D$104,MATCH(TEXT($B$3,"YYYY-MM-DD")&"-"&15,Ventes!$I$5:$I$104,0))) | D26: =IF($A26="","",INDEX(Ventes!$E$5:$E$104,MATCH(TEXT($B$3,"YYYY-MM-DD")&"-"&15,Ventes!$I$5:$I$104,0))) | E26: =IF($A26="","",INDEX(Ventes!$F$5:$F$104,MATCH(TEXT($B$3,"YYYY-MM-DD")&"-"&15,Ventes!$I$5:$I$104,0))) | F26: =IF($A26="","",INDEX(Ventes!$G$5:$G$104,MATCH(TEXT($B$3,"YYYY-MM-DD")&"-"&15,Ventes!$I$5:$I$104,0)))
A27: =IFERROR(INDEX(Ventes!$C$5:$C$104,MATCH(TEXT($B$3,"YYYY-MM-DD")&"-"&16,Ventes!$I$5:$I$104,0)),"") | B27: =IF($A27="","",INDEX(Produits!$B:$B,MATCH($A27,Produits!$A:$A,0))) | C27: =IF($A27="","",INDEX(Ventes!$D$5:$D$104,MATCH(TEXT($B$3,"YYYY-MM-DD")&"-"&16,Ventes!$I$5:$I$104,0))) | D27: =IF($A27="","",INDEX(Ventes!$E$5:$E$104,MATCH(TEXT($B$3,"YYYY-MM-DD")&"-"&16,Ventes!$I$5:$I$104,0))) | E27: =IF($A27="","",INDEX(Ventes!$F$5:$F$104,MATCH(TEXT($B$3,"YYYY-MM-DD")&"-"&16,Ventes!$I$5:$I$104,0))) | F27: =IF($A27="","",INDEX(Ventes!$G$5:$G$104,MATCH(TEXT($B$3,"YYYY-MM-DD")&"-"&16,Ventes!$I$5:$I$104,0)))
A28: =IFERROR(INDEX(Ventes!$C$5:$C$104,MATCH(TEXT($B$3,"YYYY-MM-DD")&"-"&17,Ventes!$I$5:$I$104,0)),"") | B28: =IF($A28="","",INDEX(Produits!$B:$B,MATCH($A28,Produits!$A:$A,0))) | C28: =IF($A28="","",INDEX(Ventes!$D$5:$D$104,MATCH(TEXT($B$3,"YYYY-MM-DD")&"-"&17,Ventes!$I$5:$I$104,0))) | D28: =IF($A28="","",INDEX(Ventes!$E$5:$E$104,MATCH(TEXT($B$3,"YYYY-MM-DD")&"-"&17,Ventes!$I$5:$I$104,0))) | E28: =IF($A28="","",INDEX(Ventes!$F$5:$F$104,MATCH(TEXT($B$3,"YYYY-MM-DD")&"-"&17,Ventes!$I$5:$I$104,0))) | F28: =IF($A28="","",INDEX(Ventes!$G$5:$G$104,MATCH(TEXT($B$3,"YYYY-MM-DD")&"-"&17,Ventes!$I$5:$I$104,0)))
A29: =IFERROR(INDEX(Ventes!$C$5:$C$104,MATCH(TEXT($B$3,"YYYY-MM-DD")&"-"&18,Ventes!$I$5:$I$104,0)),"") | B29: =IF($A29="","",INDEX(Produits!$B:$B,MATCH($A29,Produits!$A:$A,0))) | C29: =IF($A29="","",INDEX(Ventes!$D$5:$D$104,MATCH(TEXT($B$3,"YYYY-MM-DD")&"-"&18,Ventes!$I$5:$I$104,0))) | D29: =IF($A29="","",INDEX(Ventes!$E$5:$E$104,MATCH(TEXT($B$3,"YYYY-MM-DD")&"-"&18,Ventes!$I$5:$I$104,0))) | E29: =IF($A29="","",INDEX(Ventes!$F$5:$F$104,MATCH(TEXT($B$3,"YYYY-MM-DD")&"-"&18,Ventes!$I$5:$I$104,0))) | F29: =IF($A29="","",INDEX(Ventes!$G$5:$G$104,MATCH(TEXT($B$3,"YYYY-MM-DD")&"-"&18,Ventes!$I$5:$I$104,0)))
A30: =IFERROR(INDEX(Ventes!$C$5:$C$104,MATCH(TEXT($B$3,"YYYY-MM-DD")&"-"&19,Ventes!$I$5:$I$104,0)),"") | B30: =IF($A30="","",INDEX(Produits!$B:$B,MATCH($A30,Produits!$A:$A,0))) | C30: =IF($A30="","",INDEX(Ventes!$D$5:$D$104,MATCH(TEXT($B$3,"YYYY-MM-DD")&"-"&19,Ventes!$I$5:$I$104,0))) | D30: =IF($A30="","",INDEX(Ventes!$E$5:$E$104,MATCH(TEXT($B$3,"YYYY-MM-DD")&"-"&19,Ventes!$I$5:$I$104,0))) | E30: =IF($A30="","",INDEX(Ventes!$F$5:$F$104,MATCH(TEXT($B$3,"YYYY-MM-DD")&"-"&19,Ventes!$I$5:$I$104,0))) | F30: =IF($A30="","",INDEX(Ventes!$G$5:$G$104,MATCH(TEXT($B$3,"YYYY-MM-DD")&"-"&19,Ventes!$I$5:$I$104,0)))
A31: =IFERROR(INDEX(Ventes!$C$5:$C$104,MATCH(TEXT($B$3,"YYYY-MM-DD")&"-"&20,Ventes!$I$5:$I$104,0)),"") | B31: =IF($A31="","",INDEX(Produits!$B:$B,MATCH($A31,Produits!$A:$A,0))) | C31: =IF($A31="","",INDEX(Ventes!$D$5:$D$104,MATCH(TEXT($B$3,"YYYY-MM-DD")&"-"&20,Ventes!$I$5:$I$104,0))) | D31: =IF($A31="","",INDEX(Ventes!$E$5:$E$104,MATCH(TEXT($B$3,"YYYY-MM-DD")&"-"&20,Ventes!$I$5:$I$104,0))) | E31: =IF($A31="","",INDEX(Ventes!$F$5:$F$104,MATCH(TEXT($B$3,"YYYY-MM-DD")&"-"&20,Ventes!$I$5:$I$104,0))) | F31: =IF($A31="","",INDEX(Ventes!$G$5:$G$104,MATCH(TEXT($B$3,"YYYY-MM-DD")&"-"&20,Ventes!$I$5:$I$104,0)))

Sheet Fiche du jour
A1: FICHE DU JOUR
A2: =TODAY()
A4: CA du jour | B4: =SUMPRODUCT((INT(Ventes!$A$5:$A$104)=TODAY())*Ventes!$F$5:$F$104)
A5: Bénéfice du jour | B5: =SUMPRODUCT((INT(Ventes!$A$5:$A$104)=TODAY())*Ventes!$G$5:$G$104)
A6: Nb ventes du jour | B6: =COUNTIFS(Ventes!$A$5:$A$104,">="&TODAY(),Ventes!$A$5:$A$104,"<"&TODAY()+1)
A7: Nb achats du jour | B7: =COUNTIFS(Achats!$A$5:$A$104,">="&TODAY(),Achats!$A$5:$A$104,"<"&TODAY()+1)
A8: CA du mois | B8: =SUMPRODUCT((TEXT(Ventes!$A$5:$A$104,"YYYY-MM")=TEXT(TODAY(),"YYYY-MM"))*Ventes!$F$5:$F$104)
A9: Bénéfice du mois | B9: =SUMPRODUCT((TEXT(Ventes!$A$5:$A$104,"YYYY-MM")=TEXT(TODAY(),"YYYY-MM"))*Ventes!$G$5:$G$104)
A10: Produits à commander | B10: =COUNTIF(Produits!$I$5:$I$104,"A COMMANDER")
A11: Valeur du stock | B11: =SUMPRODUCT(Produits!$C$5:$C$19,Produits!$H$5:$H$19)

Sheet Prix dynamiques
A1: PRIX DYNAMIQUES
A2: Marge cible en D2. | C2: Marge cible : | D2: 0.25
A4: SKU | B4: Produit | C4: Prix achat | D4: Marge % | E4: Prix plancher | F4: Prix conseillé | G4: Prix actuel | H4: Statut
A5: =Produits!A5 | B5: =Produits!B5 | C5: =Produits!C5 | D5: =$D$2 | E5: =ROUND(C5*(1+D5),0) | F5: =CEILING(E5,5000) | G5: =Produits!D5 | H5: =IF(G5<E5,"SOUS LE PLANCHER",IF(G5<F5,"A AJUSTER","OK"))
A6: =Produits!A6 | B6: =Produits!B6 | C6: =Produits!C6 | D6: =$D$2 | E6: =ROUND(C6*(1+D6),0) | F6: =CEILING(E6,5000) | G6: =Produits!D6 | H6: =IF(G6<E6,"SOUS LE PLANCHER",IF(G6<F6,"A AJUSTER","OK"))
A7: =Produits!A7 | B7: =Produits!B7 | C7: =Produits!C7 | D7: =$D$2 | E7: =ROUND(C7*(1+D7),0) | F7: =CEILING(E7,5000) | G7: =Produits!D7 | H7: =IF(G7<E7,"SOUS LE PLANCHER",IF(G7<F7,"A AJUSTER","OK"))
A8: =Produits!A8 | B8: =Produits!B8 | C8: =Produits!C8 | D8: =$D$2 | E8: =ROUND(C8*(1+D8),0) | F8: =CEILING(E8,5000) | G8: =Produits!D8 | H8: =IF(G8<E8,"SOUS LE PLANCHER",IF(G8<F8,"A AJUSTER","OK"))
A9: =Produits!A9 | B9: =Produits!B9 | C9: =Produits!C9 | D9: =$D$2 | E9: =ROUND(C9*(1+D9),0) | F9: =CEILING(E9,5000) | G9: =Produits!D9 | H9: =IF(G9<E9,"SOUS LE PLANCHER",IF(G9<F9,"A AJUSTER","OK"))
A10: =Produits!A10 | B10: =Produits!B10 | C10: =Produits!C10 | D10: =$D$2 | E10: =ROUND(C10*(1+D10),0) | F10: =CEILING(E10,5000) | G10: =Produits!D10 | H10: =IF(G10<E10,"SOUS LE PLANCHER",IF(G10<F10,"A AJUSTER","OK"))
A11: =Produits!A11 | B11: =Produits!B11 | C11: =Produits!C11 | D11: =$D$2 | E11: =ROUND(C11*(1+D11),0) | F11: =CEILING(E11,5000) | G11: =Produits!D11 | H11: =IF(G11<E11,"SOUS LE PLANCHER",IF(G11<F11,"A AJUSTER","OK"))
A12: =Produits!A12 | B12: =Produits!B12 | C12: =Produits!C12 | D12: =$D$2 | E12: =ROUND(C12*(1+D12),0) | F12: =CEILING(E12,5000) | G12: =Produits!D12 | H12: =IF(G12<E12,"SOUS LE PLANCHER",IF(G12<F12,"A AJUSTER","OK"))
A13: =Produits!A13 | B13: =Produits!B13 | C13: =Produits!C13 | D13: =$D$2 | E13: =ROUND(C13*(1+D13),0) | F13: =CEILING(E13,5000) | G13: =Produits!D13 | H13: =IF(G13<E13,"SOUS LE PLANCHER",IF(G13<F13,"A AJUSTER","OK"))
A14: =Produits!A14 | B14: =Produits!B14 | C14: =Produits!C14 | D14: =$D$2 | E14: =ROUND(C14*(1+D14),0) | F14: =CEILING(E14,5000) | G14: =Produits!D14 | H14: =IF(G14<E14,"SOUS LE PLANCHER",IF(G14<F14,"A AJUSTER","OK"))
A15: =Produits!A15 | B15: =Produits!B15 | C15: =Produits!C15 | D15: =$D$2 | E15: =ROUND(C15*(1+D15),0) | F15: =CEILING(E15,5000) | G15: =Produits!D15 | H15: =IF(G15<E15,"SOUS LE PLANCHER",IF(G15<F15,"A AJUSTER","OK"))
A16: =Produits!A16 | B16: =Produits!B16 | C16: =Produits!C16 | D16: =$D$2 | E16: =ROUND(C16*(1+D16),0) | F16: =CEILING(E16,5000) | G16: =Produits!D16 | H16: =IF(G16<E16,"SOUS LE PLANCHER",IF(G16<F16,"A AJUSTER","OK"))
... A19: =Produits!A19 | B19: =Produits!B19 | C19: =Produits!C19 | D19: =$D$2 | E19: =ROUND(C19*(1+D19),0) | F19: =CEILING(E19,5000) | G19: =Produits!D19 | H19: =IF(G19<E19,"SOUS LE PLANCHER",IF(G19<F19,"A AJUSTER","OK"))

Sheet Alertes
A1: ALERTES DE STOCK
A2: Feuille automatique.
A4: SKU | B4: Produit | C4: Stock | D4: Seuil | E4: Qté à commander | F4: Priorité
A5: =IFERROR(INDEX(Produits!$A$5:$A$19,MATCH(1,Produits!$L$5:$L$19,0)),"") | B5: =IF($A5="","",INDEX(Produits!$B:$B,MATCH($A5,Produits!$A:$A,0))) | C5: =IF($A5="","",INDEX(Produits!$H:$H,MATCH($A5,Produits!$A:$A,0))) | D5: =IF($A5="","",INDEX(Produits!$J:$J,MATCH($A5,Produits!$A:$A,0))) | E5: =IF($A5="","",MAX(3,D5*2-C5)) | F5: =IF($A5="","",IF(C5=0,"URGENT",IF(C5<=D5/2,"HAUT","NORMAL")))
A6: =IFERROR(INDEX(Produits!$A$5:$A$19,MATCH(2,Produits!$L$5:$L$19,0)),"") | B6: =IF($A6="","",INDEX(Produits!$B:$B,MATCH($A6,Produits!$A:$A,0))) | C6: =IF($A6="","",INDEX(Produits!$H:$H,MATCH($A6,Produits!$A:$A,0))) | D6: =IF($A6="","",INDEX(Produits!$J:$J,MATCH($A6,Produits!$A:$A,0))) | E6: =IF($A6="","",MAX(3,D6*2-C6)) | F6: =IF($A6="","",IF(C6=0,"URGENT",IF(C6<=D6/2,"HAUT","NORMAL")))
A7: =IFERROR(INDEX(Produits!$A$5:$A$19,MATCH(3,Produits!$L$5:$L$19,0)),"") | B7: =IF($A7="","",INDEX(Produits!$B:$B,MATCH($A7,Produits!$A:$A,0))) | C7: =IF($A7="","",INDEX(Produits!$H:$H,MATCH($A7,Produits!$A:$A,0))) | D7: =IF($A7="","",INDEX(Produits!$J:$J,MATCH($A7,Produits!$A:$A,0))) | E7: =IF($A7="","",MAX(3,D7*2-C7)) | F7: =IF($A7="","",IF(C7=0,"URGENT",IF(C7<=D7/2,"HAUT","NORMAL")))
A8: =IFERROR(INDEX(Produits!$A$5:$A$19,MATCH(4,Produits!$L$5:$L$19,0)),"") | B8: =IF($A8="","",INDEX(Produits!$B:$B,MATCH($A8,Produits!$A:$A,0))) | C8: =IF($A8="","",INDEX(Produits!$H:$H,MATCH($A8,Produits!$A:$A,0))) | D8: =IF($A8="","",INDEX(Produits!$J:$J,MATCH($A8,Produits!$A:$A,0))) | E8: =IF($A8="","",MAX(3,D8*2-C8)) | F8: =IF($A8="","",IF(C8=0,"URGENT",IF(C8<=D8/2,"HAUT","NORMAL")))
A9: =IFERROR(INDEX(Produits!$A$5:$A$19,MATCH(5,Produits!$L$5:$L$19,0)),"") | B9: =IF($A9="","",INDEX(Produits!$B:$B,MATCH($A9,Produits!$A:$A,0))) | C9: =IF($A9="","",INDEX(Produits!$H:$H,MATCH($A9,Produits!$A:$A,0))) | D9: =IF($A9="","",INDEX(Produits!$J:$J,MATCH($A9,Produits!$A:$A,0))) | E9: =IF($A9="","",MAX(3,D9*2-C9)) | F9: =IF($A9="","",IF(C9=0,"URGENT",IF(C9<=D9/2,"HAUT","NORMAL")))
A10: =IFERROR(INDEX(Produits!$A$5:$A$19,MATCH(6,Produits!$L$5:$L$19,0)),"") | B10: =IF($A10="","",INDEX(Produits!$B:$B,MATCH($A10,Produits!$A:$A,0))) | C10: =IF($A10="","",INDEX(Produits!$H:$H,MATCH($A10,Produits!$A:$A,0))) | D10: =IF($A10="","",INDEX(Produits!$J:$J,MATCH($A10,Produits!$A:$A,0))) | E10: =IF($A10="","",MAX(3,D10*2-C10)) | F10: =IF($A10="","",IF(C10=0,"URGENT",IF(C10<=D10/2,"HAUT","NORMAL")))
A11: =IFERROR(INDEX(Produits!$A$5:$A$19,MATCH(7,Produits!$L$5:$L$19,0)),"") | B11: =IF($A11="","",INDEX(Produits!$B:$B,MATCH($A11,Produits!$A:$A,0))) | C11: =IF($A11="","",INDEX(Produits!$H:$H,MATCH($A11,Produits!$A:$A,0))) | D11: =IF($A11="","",INDEX(Produits!$J:$J,MATCH($A11,Produits!$A:$A,0))) | E11: =IF($A11="","",MAX(3,D11*2-C11)) | F11: =IF($A11="","",IF(C11=0,"URGENT",IF(C11<=D11/2,"HAUT","NORMAL")))
A12: =IFERROR(INDEX(Produits!$A$5:$A$19,MATCH(8,Produits!$L$5:$L$19,0)),"") | B12: =IF($A12="","",INDEX(Produits!$B:$B,MATCH($A12,Produits!$A:$A,0))) | C12: =IF($A12="","",INDEX(Produits!$H:$H,MATCH($A12,Produits!$A:$A,0))) | D12: =IF($A12="","",INDEX(Produits!$J:$J,MATCH($A12,Produits!$A:$A,0))) | E12: =IF($A12="","",MAX(3,D12*2-C12)) | F12: =IF($A12="","",IF(C12=0,"URGENT",IF(C12<=D12/2,"HAUT","NORMAL")))
A13: =IFERROR(INDEX(Produits!$A$5:$A$19,MATCH(9,Produits!$L$5:$L$19,0)),"") | B13: =IF($A13="","",INDEX(Produits!$B:$B,MATCH($A13,Produits!$A:$A,0))) | C13: =IF($A13="","",INDEX(Produits!$H:$H,MATCH($A13,Produits!$A:$A,0))) | D13: =IF($A13="","",INDEX(Produits!$J:$J,MATCH($A13,Produits!$A:$A,0))) | E13: =IF($A13="","",MAX(3,D13*2-C13)) | F13: =IF($A13="","",IF(C13=0,"URGENT",IF(C13<=D13/2,"HAUT","NORMAL")))
A14: =IFERROR(INDEX(Produits!$A$5:$A$19,MATCH(10,Produits!$L$5:$L$19,0)),"") | B14: =IF($A14="","",INDEX(Produits!$B:$B,MATCH($A14,Produits!$A:$A,0))) | C14: =IF($A14="","",INDEX(Produits!$H:$H,MATCH($A14,Produits!$A:$A,0))) | D14: =IF($A14="","",INDEX(Produits!$J:$J,MATCH($A14,Produits!$A:$A,0))) | E14: =IF($A14="","",MAX(3,D14*2-C14)) | F14: =IF($A14="","",IF(C14=0,"URGENT",IF(C14<=D14/2,"HAUT","NORMAL")))
A15: =IFERROR(INDEX(Produits!$A$5:$A$19,MATCH(11,Produits!$L$5:$L$19,0)),"") | B15: =IF($A15="","",INDEX(Produits!$B:$B,MATCH($A15,Produits!$A:$A,0))) | C15: =IF($A15="","",INDEX(Produits!$H:$H,MATCH($A15,Produits!$A:$A,0))) | D15: =IF($A15="","",INDEX(Produits!$J:$J,MATCH($A15,Produits!$A:$A,0))) | E15: =IF($A15="","",MAX(3,D15*2-C15)) | F15: =IF($A15="","",IF(C15=0,"URGENT",IF(C15<=D15/2,"HAUT","NORMAL")))
A16: =IFERROR(INDEX(Produits!$A$5:$A$19,MATCH(12,Produits!$L$5:$L$19,0)),"") | B16: =IF($A16="","",INDEX(Produits!$B:$B,MATCH($A16,Produits!$A:$A,0))) | C16: =IF($A16="","",INDEX(Produits!$H:$H,MATCH($A16,Produits!$A:$A,0))) | D16: =IF($A16="","",INDEX(Produits!$J:$J,MATCH($A16,Produits!$A:$A,0))) | E16: =IF($A16="","",MAX(3,D16*2-C16)) | F16: =IF($A16="","",IF(C16=0,"URGENT",IF(C16<=D16/2,"HAUT","NORMAL")))
A17: =IFERROR(INDEX(Produits!$A$5:$A$19,MATCH(13,Produits!$L$5:$L$19,0)),"") | B17: =IF($A17="","",INDEX(Produits!$B:$B,MATCH($A17,Produits!$A:$A,0))) | C17: =IF($A17="","",INDEX(Produits!$H:$H,MATCH($A17,Produits!$A:$A,0))) | D17: =IF($A17="","",INDEX(Produits!$J:$J,MATCH($A17,Produits!$A:$A,0))) | E17: =IF($A17="","",MAX(3,D17*2-C17)) | F17: =IF($A17="","",IF(C17=0,"URGENT",IF(C17<=D17/2,"HAUT","NORMAL")))
A18: =IFERROR(INDEX(Produits!$A$5:$A$19,MATCH(14,Produits!$L$5:$L$19,0)),"") | B18: =IF($A18="","",INDEX(Produits!$B:$B,MATCH($A18,Produits!$A:$A,0))) | C18: =IF($A18="","",INDEX(Produits!$H:$H,MATCH($A18,Produits!$A:$A,0))) | D18: =IF($A18="","",INDEX(Produits!$J:$J,MATCH($A18,Produits!$A:$A,0))) | E18: =IF($A18="","",MAX(3,D18*2-C18)) | F18: =IF($A18="","",IF(C18=0,"URGENT",IF(C18<=D18/2,"HAUT","NORMAL")))
A19: =IFERROR(INDEX(Produits!$A$5:$A$19,MATCH(15,Produits!$L$5:$L$19,0)),"") | B19: =IF($A19="","",INDEX(Produits!$B:$B,MATCH($A19,Produits!$A:$A,0))) | C19: =IF($A19="","",INDEX(Produits!$H:$H,MATCH($A19,Produits!$A:$A,0))) | D19: =IF($A19="","",INDEX(Produits!$J:$J,MATCH($A19,Produits!$A:$A,0))) | E19: =IF($A19="","",MAX(3,D19*2-C19)) | F19: =IF($A19="","",IF(C19=0,"URGENT",IF(C19<=D19/2,"HAUT","NORMAL")))
A20: =IFERROR(INDEX(Produits!$A$5:$A$19,MATCH(16,Produits!$L$5:$L$19,0)),"") | B20: =IF($A20="","",INDEX(Produits!$B:$B,MATCH($A20,Produits!$A:$A,0))) | C20: =IF($A20="","",INDEX(Produits!$H:$H,MATCH($A20,Produits!$A:$A,0))) | D20: =IF($A20="","",INDEX(Produits!$J:$J,MATCH($A20,Produits!$A:$A,0))) | E20: =IF($A20="","",MAX(3,D20*2-C20)) | F20: =IF($A20="","",IF(C20=0,"URGENT",IF(C20<=D20/2,"HAUT","NORMAL")))
A21: =IFERROR(INDEX(Produits!$A$5:$A$19,MATCH(17,Produits!$L$5:$L$19,0)),"") | B21: =IF($A21="","",INDEX(Produits!$B:$B,MATCH($A21,Produits!$A:$A,0))) | C21: =IF($A21="","",INDEX(Produits!$H:$H,MATCH($A21,Produits!$A:$A,0))) | D21: =IF($A21="","",INDEX(Produits!$J:$J,MATCH($A21,Produits!$A:$A,0))) | E21: =IF($A21="","",MAX(3,D21*2-C21)) | F21: =IF($A21="","",IF(C21=0,"URGENT",IF(C21<=D21/2,"HAUT","NORMAL")))
A22: =IFERROR(INDEX(Produits!$A$5:$A$19,MATCH(18,Produits!$L$5:$L$19,0)),"") | B22: =IF($A22="","",INDEX(Produits!$B:$B,MATCH($A22,Produits!$A:$A,0))) | C22: =IF($A22="","",INDEX(Produits!$H:$H,MATCH($A22,Produits!$A:$A,0))) | D22: =IF($A22="","",INDEX(Produits!$J:$J,MATCH($A22,Produits!$A:$A,0))) | E22: =IF($A22="","",MAX(3,D22*2-C22)) | F22: =IF($A22="","",IF(C22=0,"URGENT",IF(C22<=D22/2,"HAUT","NORMAL")))
A23: =IFERROR(INDEX(Produits!$A$5:$A$19,MATCH(19,Produits!$L$5:$L$19,0)),"") | B23: =IF($A23="","",INDEX(Produits!$B:$B,MATCH($A23,Produits!$A:$A,0))) | C23: =IF($A23="","",INDEX(Produits!$H:$H,MATCH($A23,Produits!$A:$A,0))) | D23: =IF($A23="","",INDEX(Produits!$J:$J,MATCH($A23,Produits!$A:$A,0))) | E23: =IF($A23="","",MAX(3,D23*2-C23)) | F23: =IF($A23="","",IF(C23=0,"URGENT",IF(C23<=D23/2,"HAUT","NORMAL")))
A24: =IFERROR(INDEX(Produits!$A$5:$A$19,MATCH(20,Produits!$L$5:$L$19,0)),"") | B24: =IF($A24="","",INDEX(Produits!$B:$B,MATCH($A24,Produits!$A:$A,0))) | C24: =IF($A24="","",INDEX(Produits!$H:$H,MATCH($A24,Produits!$A:$A,0))) | D24: =IF($A24="","",INDEX(Produits!$J:$J,MATCH($A24,Produits!$A:$A,0))) | E24: =IF($A24="","",MAX(3,D24*2-C24)) | F24: =IF($A24="","",IF(C24=0,"URGENT",IF(C24<=D24/2,"HAUT","NORMAL")))

Sheet Top produits
A1: TOP PRODUITS — Classement par CA
A2: Tri automatique par chiffre d'affaires décroissant.
A4: Rang | B4: SKU | C4: Produit | D4: Qté vendue | E4: CA généré | F4: Marge totale | G4: Marge %
A5: 1 | B5: =IFERROR(INDEX($I$5:$I$19,MATCH($E5,$J$5:$J$19,0)),"") | C5: =IFERROR(INDEX(Produits!$B:$B,MATCH($B5,Produits!$A:$A,0)),"") | D5: =IFERROR(INDEX($K$5:$K$19,MATCH($E5,$J$5:$J$19,0)),0) | E5: =LARGE($J$5:$J$19,1) | F5: =IFERROR(INDEX($L$5:$L$19,MATCH($E5,$J$5:$J$19,0)),0) | G5: =IF(OR($E5=0,$E5=""),"",$F5/$E5) | I5: =Produits!A5 | J5: =SUMIF(Ventes!$C$5:$C$104,$I5,Ventes!$F$5:$F$104) | K5: =SUMIF(Ventes!$C$5:$C$104,$I5,Ventes!$D$5:$D$104) | L5: =SUMIF(Ventes!$C$5:$C$104,$I5,Ventes!$G$5:$G$104)
A6: 2 | B6: =IFERROR(INDEX($I$5:$I$19,MATCH($E6,$J$5:$J$19,0)),"") | C6: =IFERROR(INDEX(Produits!$B:$B,MATCH($B6,Produits!$A:$A,0)),"") | D6: =IFERROR(INDEX($K$5:$K$19,MATCH($E6,$J$5:$J$19,0)),0) | E6: =LARGE($J$5:$J$19,2) | F6: =IFERROR(INDEX($L$5:$L$19,MATCH($E6,$J$5:$J$19,0)),0) | G6: =IF(OR($E6=0,$E6=""),"",$F6/$E6) | I6: =Produits!A6 | J6: =SUMIF(Ventes!$C$5:$C$104,$I6,Ventes!$F$5:$F$104) | K6: =SUMIF(Ventes!$C$5:$C$104,$I6,Ventes!$D$5:$D$104) | L6: =SUMIF(Ventes!$C$5:$C$104,$I6,Ventes!$G$5:$G$104)
